Workbook

Sheet 104095 DEERFIELD  104143 SCOBIE
A1: ****** Plant Redispatch calculator ******* !!!! Please - edit only columns 'Status' & 'Pnew' !!!!!***
A3: Flows
A4: NN | B4: LFCaseName | C4: Monitored Element | I4: Contingency | J4: Limit | K4: FlowInit | L4: FlowRes | M4: FlowChange | N4: Loading
A5: 1 | C5: 104095 DEERFIELD 345 104143 SCOBIE POND 345 1 | I5: BF_SEBRK_169 | J5: 1358 | K5: 797.9 | L5: ='104095 DEERFIELD 104143 SCOBIE'!K5+'104095 DEERFIELD 104143 SCOBIE'!M5 | M5: =N8 | N5: ='104095 DEERFIELD 104143 SCOBIE'!L5/'104095 DEERFIELD 104143 SCOBIE'!J5
A8: Dispatch | J8: =SUM(J10:J733) | N8: =SUM(N10:N733)
A9: Bus# | B9: Bus Name | C9: Volt | D9: Area | E9: Zone | F9: Pgen or Pload | G9: PMin Gen | H9: PMax Gen | I9: Pnew | J9: Pdelta | K9: Pavail | L9: Dfax_1 | M9: --- | N9: Impact_1
A10: 911550 | B10: PH2_DGEN | C10: 345 | D10: 101 | E10: 1120 | F10: 353.9 | G10: 0 | H10: 700 | I10: 353.9 | J10: =I10-F10 | K10: =H10-I10 | L10: -0.06228 | N10: =L10*J10
A11: 990759 | B11: BAT_MYSTIC~1 | C11: 345 | D11: 101 | E11: 1000 | F11: 276 | G11: 0 | H11: 276 | I11: 276 | J11: =I11-F11 | K11: =H11-I11 | L11: -0.06013 | N11: =L11*J11
A12: 991802 | B12: BAT_MYSTIC_R | C12: 345 | D12: 101 | E12: 1000 | F12: 507 | G12: 0 | H12: 507 | I12: 507 | J12: =I12-F12 | K12: =H12-I12 | L12: -0.06013 | N12: =L12*J12
A13: 993997 | B13: DFO NG_MID~1 | C13: 115 | D13: 101 | E13: 1120 | F13: 23 | G13: 0 | H13: 23 | I13: 23 | J13: =I13-F13 | K13: =H13-I13 | L13: -0.05994 | N13: =L13*J13
A14: 114713 | B14: WATERS RVRJ1 | C14: 13.8 | D14: 101 | E14: 1242 | F14: 16.44 | G14: 0 | H14: 16.44 | I14: 16.44 | J14: =I14-F14 | K14: =H14-I14 | L14: -0.05876 | N14: =L14*J14
A15: 994421 | B15: DFO NG_WAT~1 | C15: 115 | D15: 101 | E15: 1130 | F15: 61.85 | G15: 0 | H15: 61.85 | I15: 61.85 | J15: =I15-F15 | K15: =H15-I15 | L15: -0.05876 | N15: =L15*J15
A16: 114714 | B16: WATERS RVRJ2 | C16: 13.8 | D16: 101 | E16: 1242 | F16: 30.79 | G16: 0 | H16: 30.79 | I16: 30.79 | J16: =I16-F16 | K16: =H16-I16 | L16: -0.05867 | N16: =L16*J16
A17: 114716 | B17: MMWEC WR | C17: 13.8 | D17: 101 | E17: 1242 | F17: 57.97 | G17: 0 | H17: 57.97 | I17: 57.97 | J17: =I17-F17 | K17: =H17-I17 | L17: -0.05867 | N17: =L17*J17
A18: 114070 | B18: OGDEN-MARTIN | C18: 13.8 | D18: 101 | E18: 1120 | F18: 41.68 | G18: 0 | H18: 41.68 | I18: 41.68 | J18: =I18-F18 | K18: =H18-I18 | L18: -0.05838 | N18: =L18*J18
A19: 114069 | B19: WHLABRATR NA | C19: 13.8 | D19: 101 | E19: 1120 | F19: 40 | G19: 0 | H19: 40 | I19: 40 | J19: =I19-F19 | K19: =H19-I19 | L19: -0.05838 | N19: =L19*J19
A20: 111123 | B20: KENDALL ST B | C20: 13.8 | D20: 101 | E20: 1013 | F20: 27.75 | G20: 0 | H20: 27.75 | I20: 27.75 | J20: =I20-F20 | K20: =H20-I20 | L20: -0.05829 | N20: =L20*J20
A21: 111126 | B21: KENDALL CT | C21: 18 | D21: 101 | E21: 1013 | F21: 170 | G21: 0 | H21: 170 | I21: 170 | J21: =I21-F21 | K21: =H21-I21 | L21: -0.05829 | N21: =L21*J21
... A733: 105478 | B733: NEWINGTON_S1 | C733: 18 | D733: 101 | E733: 603 | F733: 208.95 | G733: 0 | H733: 208.95 | I733: 208.95 | J733: =I733-F733 | K733: =H733-I733 | L733: 0.60341 | N733: =L733*J733

Sheet 107931 NE_K6_NY 107930 BENNINGT
A1: ****** Plant Redispatch calculator ******* !!!! Please - edit only columns 'Status' & 'Pnew' !!!!!***
A3: Flows
A4: NN | B4: LFCaseName | C4: Monitored Element | I4: Contingency | J4: Limit | K4: FlowInit | L4: FlowRes | M4: FlowChange | N4: Loading
A5: 1 | C5: 107931 NE_K6_NY 115 107930 BENNINGTON 115 1 | I5: BF_NTHFLD_2T | J5: 217 | K5: 111.2 | L5: ='107931 NE_K6_NY 107930 BENNINGT'!K5+'107931 NE_K6_NY 107930 BENNINGT'!M5 | M5: =N8 | N5: ='107931 NE_K6_NY 107930 BENNINGT'!L5/'107931 NE_K6_NY 107930 BENNINGT'!J5
A8: Dispatch | J8: =SUM(J10:J733) | N8: =SUM(N10:N733)
A9: Bus# | B9: Bus Name | C9: Volt | D9: Area | E9: Zone | F9: Pgen or Pload | G9: PMin Gen | H9: PMax Gen | I9: Pnew | J9: Pdelta | K9: Pavail | L9: Dfax_1 | M9: --- | N9: Impact_1
A10: 998496 | B10: SUN_E ARLN~1 | C10: 46 | D10: 101 | E10: 822 | F10: 0 | G10: 0 | H10: 0 | I10: 0 | J10: =I10-F10 | K10: =H10-I10 | L10: -0.3125 | N10: =L10*J10
A11: 109403 | B11: DRFLD EAST G | C11: 0.69 | D11: 101 | E11: 704 | F11: 0 | G11: 0 | H11: 0 | I11: 0 | J11: =I11-F11 | K11: =H11-I11 | L11: -0.26194 | N11: =L11*J11
A12: 109404 | B12: DRFLD WEST G | C12: 0.69 | D12: 101 | E12: 704 | F12: 0 | G12: 0 | H12: 0 | I12: 0 | J12: =I12-F12 | K12: =H12-I12 | L12: -0.26194 | N12: =L12*J12
A13: 109296 | B13: SEARS WIND_E | C13: 12.5 | D13: 101 | E13: 704 | F13: 0 | G13: 0 | H13: 0 | I13: 0 | J13: =I13-F13 | K13: =H13-I13 | L13: -0.24714 | N13: =L13*J13
A14: 109297 | B14: SEARS WIND_W | C14: 12.5 | D14: 101 | E14: 704 | F14: 0 | G14: 0 | H14: 0 | I14: 0 | J14: =I14-F14 | K14: =H14-I14 | L14: -0.24714 | N14: =L14*J14
A15: 109517 | B15: SEARS HYDRO | C15: 2.4 | D15: 101 | E15: 1100 | F15: 0 | G15: 0 | H15: 0 | I15: 0 | J15: =I15-F15 | K15: =H15-I15 | L15: -0.2325 | N15: =L15*J15
A16: 108934 | B16: STRATTON_SC1 | C16: 13.8 | D16: 101 | E16: 704 | F16: 0 | G16: 0 | H16: 0 | I16: 0 | J16: =I16-F16 | K16: =H16-I16 | L16: -0.19111 | N16: =L16*J16
A17: 108938 | B17: STRATTON_SC2 | C17: 13.8 | D17: 101 | E17: 704 | F17: 0 | G17: 0 | H17: 0 | I17: 0 | J17: =I17-F17 | K17: =H17-I17 | L17: -0.19111 | N17: =L17*J17
A18: 109503 | B18: HARRIMAN G3 | C18: 6.9 | D18: 101 | E18: 1100 | F18: 0 | G18: 0 | H18: 0 | I18: 0 | J18: =I18-F18 | K18: =H18-I18 | L18: -0.17463 | N18: =L18*J18
A19: 113125 | B19: HOOSAC CLR2 | C19: 0.69 | D19: 101 | E19: 1100 | F19: 0 | G19: 0 | H19: 0 | I19: 0 | J19: =I19-F19 | K19: =H19-I19 | L19: -0.15678 | N19: =L19*J19
A20: 113123 | B20: HOOSAC CLR1 | C20: 0.69 | D20: 101 | E20: 1100 | F20: 0 | G20: 0 | H20: 0 | I20: 0 | J20: =I20-F20 | K20: =H20-I20 | L20: -0.15678 | N20: =L20*J20
A21: 113101 | B21: DEERFIELD 5G | C21: 13.8 | D21: 101 | E21: 1100 | F21: 0 | G21: 0 | H21: 0 | I21: 0 | J21: =I21-F21 | K21: =H21-I21 | L21: -0.15534 | N21: =L21*J21
... A733: 911554 | B733: NYNE_OSWG | C733: 345 | D733: 102 | E733: 12 | F733: 120.67 | G733: 0 | H733: 466.67 | I733: 120.67 | J733: =I733-F733 | K733: =H733-I733 | L733: 0.05947 | N733: =L733*J733

Sheet 113001 BEAR SWAMP 113008 BEAR S
A1: ****** Plant Redispatch calculator ******* !!!! Please - edit only columns 'Status' & 'Pnew' !!!!!***
A3: Flows
A4: NN | B4: LFCaseName | C4: Monitored Element | I4: Contingency | J4: Limit | K4: FlowInit | L4: FlowRes | M4: FlowChange | N4: Loading
A5: 1 | C5: 113001 BEAR SWAMP 230 113008 BEAR SWAMP 115 5 | I5: NF_BSWMP_4X | J5: 480 | K5: 313.4 | L5: ='113001 BEAR SWAMP 113008 BEAR S'!K5+'113001 BEAR SWAMP 113008 BEAR S'!M5 | M5: =N8 | N5: ='113001 BEAR SWAMP 113008 BEAR S'!L5/'113001 BEAR SWAMP 113008 BEAR S'!J5
A8: Dispatch | J8: =SUM(J10:J733) | N8: =SUM(N10:N733)
A9: Bus# | B9: Bus Name | C9: Volt | D9: Area | E9: Zone | F9: Pgen or Pload | G9: PMin Gen | H9: PMax Gen | I9: Pnew | J9: Pdelta | K9: Pavail | L9: Dfax_1 | M9: --- | N9: Impact_1
A10: 113100 | B10: DEERFIELD 4G | C10: 2.4 | D10: 101 | E10: 1100 | F10: 0 | G10: 0 | H10: 0 | I10: 0 | J10: =I10-F10 | K10: =H10-I10 | L10: -0.27604 | N10: =L10*J10
A11: 113099 | B11: DEERFIELD 3G | C11: 2.4 | D11: 101 | E11: 1100 | F11: 0 | G11: 0 | H11: 0 | I11: 0 | J11: =I11-F11 | K11: =H11-I11 | L11: -0.26738 | N11: =L11*J11
A12: 109504 | B12: HARRIMAN G2 | C12: 6.9 | D12: 101 | E12: 1100 | F12: 13.71 | G12: 0 | H12: 13.71 | I12: 13.71 | J12: =I12-F12 | K12: =H12-I12 | L12: -0.26539 | N12: =L12*J12
A13: 109505 | B13: HARRIMAN G1 | C13: 6.9 | D13: 101 | E13: 1100 | F13: 13.71 | G13: 0 | H13: 13.71 | I13: 13.71 | J13: =I13-F13 | K13: =H13-I13 | L13: -0.26539 | N13: =L13*J13
A14: 113098 | B14: DEERFIELD 2G | C14: 2.4 | D14: 101 | E14: 1100 | F14: 0 | G14: 0 | H14: 0 | I14: 0 | J14: =I14-F14 | K14: =H14-I14 | L14: -0.25652 | N14: =L14*J14
A15: 993005 | B15: SUN_ADAMS | C15: 115 | D15: 101 | E15: 1100 | F15: 0 | G15: 0 | H15: 0 | I15: 0 | J15: =I15-F15 | K15: =H15-I15 | L15: -0.25533 | N15: =L15*J15
A16: 113104 | B16: SHERMAN HYD | C16: 2.4 | D16: 101 | E16: 1100 | F16: 0 | G16: 0 | H16: 0 | I16: 0 | J16: =I16-F16 | K16: =H16-I16 | L16: -0.2538 | N16: =L16*J16
A17: 113101 | B17: DEERFIELD 5G | C17: 13.8 | D17: 101 | E17: 1100 | F17: 0 | G17: 0 | H17: 0 | I17: 0 | J17: =I17-F17 | K17: =H17-I17 | L17: -0.2391 | N17: =L17*J17
A18: 113102 | B18: FIFE BROOK | C18: 13.8 | D18: 101 | E18: 1100 | F18: 9.9 | G18: 0 | H18: 9.9 | I18: 9.9 | J18: =I18-F18 | K18: =H18-I18 | L18: -0.2391 | N18: =L18*J18
A19: 113125 | B19: HOOSAC CLR2 | C19: 0.69 | D19: 101 | E19: 1100 | F19: 0 | G19: 0 | H19: 0 | I19: 0 | J19: =I19-F19 | K19: =H19-I19 | L19: -0.2373 | N19: =L19*J19
A20: 113123 | B20: HOOSAC CLR1 | C20: 0.69 | D20: 101 | E20: 1100 | F20: 0 | G20: 0 | H20: 0 | I20: 0 | J20: =I20-F20 | K20: =H20-I20 | L20: -0.2373 | N20: =L20*J20
A21: 109503 | B21: HARRIMAN G3 | C21: 6.9 | D21: 101 | E21: 1100 | F21: 0 | G21: 0 | H21: 0 | I21: 0 | J21: =I21-F21 | K21: =H21-I21 | L21: -0.22906 | N21: =L21*J21
... A733: 993001 | B733: SUN_BEAR S~1 | C733: 230 | D733: 101 | E733: 1100 | F733: 83.71 | G733: 0 | H733: 83.71 | I733: 83.71 | J733: =I733-F733 | K733: =H733-I733 | L733: 0.41396 | N733: =L733*J733

Sheet 113008 BEAR SWAMP 113010 E131
A1: ****** Plant Redispatch calculator ******* !!!! Please - edit only columns 'Status' & 'Pnew' !!!!!***
A3: Flows
A4: NN | B4: LFCaseName | C4: Monitored Element | I4: Contingency | J4: Limit | K4: FlowInit | L4: FlowRes | M4: FlowChange | N4: Loading
A5: 1 | C5: 113008 BEAR SWAMP 115 113010 E131 TAP 115 1 | I5: Base Case | J5: 383 | K5: 240.8 | L5: ='113008 BEAR SWAMP 113010 E131'!K5+'113008 BEAR SWAMP 113010 E131'!M5 | M5: =S13 | N5: ='113008 BEAR SWAMP 113010 E131'!L5/'113008 BEAR SWAMP 113010 E131'!J5
A6: 2 | C6: 113008 BEAR SWAMP 115 113010 E131 TAP 115 1 | I6: LN_E205E | J6: 440 | K6: 412.8 | L6: ='113008 BEAR SWAMP 113010 E131'!K6+'113008 BEAR SWAMP 113010 E131'!M6 | M6: =T13 | N6: ='113008 BEAR SWAMP 113010 E131'!L6/'113008 BEAR SWAMP 113010 E131'!J6
A7: 3 | C7: 113008 BEAR SWAMP 115 113010 E131 TAP 115 1 | I7: BO_E205E | J7: 440 | K7: 412.8 | L7: ='113008 BEAR SWAMP 113010 E131'!K7+'113008 BEAR SWAMP 113010 E131'!M7 | M7: =U13 | N7: ='113008 BEAR SWAMP 113010 E131'!L7/'113008 BEAR SWAMP 113010 E131'!J7
A8: 4 | C8: 113008 BEAR SWAMP 115 113010 E131 TAP 115 1 | I8: TF_PRAT_8_8A | J8: 440 | K8: 412.4 | L8: ='113008 BEAR SWAMP 113010 E131'!K8+'113008 BEAR SWAMP 113010 E131'!M8 | M8: =V13 | N8: ='113008 BEAR SWAMP 113010 E131'!L8/'113008 BEAR SWAMP 113010 E131'!J8
A9: 5 | C9: 113008 BEAR SWAMP 115 113010 E131 TAP 115 1 | I9: BF_PRAT_205E | J9: 440 | K9: 412.4 | L9: ='113008 BEAR SWAMP 113010 E131'!K9+'113008 BEAR SWAMP 113010 E131'!M9 | M9: =W13 | N9: ='113008 BEAR SWAMP 113010 E131'!L9/'113008 BEAR SWAMP 113010 E131'!J9
A10: 6 | C10: 113008 BEAR SWAMP 115 113010 E131 TAP 115 1 | I10: BF_PRAT_801 | J10: 440 | K10: 411.6 | L10: ='113008 BEAR SWAMP 113010 E131'!K10+'113008 BEAR SWAMP 113010 E131'!M10 | M10: =X13 | N10: ='113008 BEAR SWAMP 113010 E131'!L10/'113008 BEAR SWAMP 113010 E131'!J10
A13: Dispatch | J13: =SUM(J15:J738) | S13: =SUM(S15:S738) | T13: =SUM(T15:T738) | U13: =SUM(U15:U738) | V13: =SUM(V15:V738) | W13: =SUM(W15:W738) | X13: =SUM(X15:X738)
A14: Bus# | B14: Bus Name | C14: Volt | D14: Area | E14: Zone | F14: Pgen or Pload | G14: PMin Gen | H14: PMax Gen | I14: Pnew | J14: Pdelta | K14: Pavail | L14: Dfax_1 | M14: Dfax_2 | N14: Dfax_3 | O14: Dfax_4 | P14: Dfax_5 | Q14: Dfax_6 | R14: --- | S14: Impact_1 | T14: Impact_2 | U14: Impact_3 | V14: Impact_4 | W14: Impact_5 | X14: Impact_6
B15: HARRIMAN G2 | C15: 6.9 | D15: 101 | E15: 1100 | F15: 13.71 | G15: 0 | H15: 13.71 | I15: 13.71 | J15: =I15-F15 | K15: =H15-I15 | L15: -0.35475 | M15: -0.27767 | N15: -0.27767 | O15: -0.27767 | P15: -0.27767 | Q15: -0.27753 | S15: =L15*J15 | T15: =M15*J15 | U15: =N15*J15 | V15: =O15*J15 | W15: =P15*J15 | X15: =Q15*J15
A16: 109505 | B16: HARRIMAN G1 | C16: 6.9 | D16: 101 | E16: 1100 | F16: 13.71 | G16: 0 | H16: 13.71 | I16: 13.71 | J16: =I16-F16 | K16: =H16-I16 | L16: -0.35475 | M16: -0.27767 | N16: -0.27767 | O16: -0.27767 | P16: -0.27767 | Q16: -0.27753 | S16: =L16*J16 | T16: =M16*J16 | U16: =N16*J16 | V16: =O16*J16 | W16: =P16*J16 | X16: =Q16*J16
A17: 993005 | B17: SUN_ADAMS | C17: 115 | D17: 101 | E17: 1100 | F17: 0 | G17: 0 | H17: 0 | I17: 0 | J17: =I17-F17 | K17: =H17-I17 | L17: -0.3463 | M17: -0.26542 | N17: -0.26542 | O17: -0.26542 | P17: -0.26542 | Q17: -0.26528 | S17: =L17*J17 | T17: =M17*J17 | U17: =N17*J17 | V17: =O17*J17 | W17: =P17*J17 | X17: =Q17*J17
A18: 113104 | B18: SHERMAN HYD | C18: 2.4 | D18: 101 | E18: 1100 | F18: 0 | G18: 0 | H18: 0 | I18: 0 | J18: =I18-F18 | K18: =H18-I18 | L18: -0.33957 | M18: -0.26532 | N18: -0.26532 | O18: -0.26532 | P18: -0.26532 | Q18: -0.26518 | S18: =L18*J18 | T18: =M18*J18 | U18: =N18*J18 | V18: =O18*J18 | W18: =P18*J18 | X18: =Q18*J18
A19: 113101 | B19: DEERFIELD 5G | C19: 13.8 | D19: 101 | E19: 1100 | F19: 0 | G19: 0 | H19: 0 | I19: 0 | J19: =I19-F19 | K19: =H19-I19 | L19: -0.32523 | M19: -0.24799 | N19: -0.24799 | O19: -0.24799 | P19: -0.24799 | Q19: -0.24785 | S19: =L19*J19 | T19: =M19*J19 | U19: =N19*J19 | V19: =O19*J19 | W19: =P19*J19 | X19: =Q19*J19
A20: 113102 | B20: FIFE BROOK | C20: 13.8 | D20: 101 | E20: 1100 | F20: 9.9 | G20: 0 | H20: 9.9 | I20: 9.9 | J20: =I20-F20 | K20: =H20-I20 | L20: -0.32523 | M20: -0.24799 | N20: -0.24799 | O20: -0.24799 | P20: -0.24799 | Q20: -0.24785 | S20: =L20*J20 | T20: =M20*J20 | U20: =N20*J20 | V20: =O20*J20 | W20: =P20*J20 | X20: =Q20*J20
A21: 113123 | B21: HOOSAC CLR1 | C21: 0.69 | D21: 101 | E21: 1100 | F21: 0 | G21: 0 | H21: 0 | I21: 0 | J21: =I21-F21 | K21: =H21-I21 | L21: -0.3229 | M21: -0.24606 | N21: -0.24606 | O21: -0.24606 | P21: -0.24606 | Q21: -0.24593 | S21: =L21*J21 | T21: =M21*J21 | U21: =N21*J21 | V21: =O21*J21 | W21: =P21*J21 | X21: =Q21*J21
A22: 113125 | B22: HOOSAC CLR2 | C22: 0.69 | D22: 101 | E22: 1100 | F22: 0 | G22: 0 | H22: 0 | I22: 0 | J22: =I22-F22 | K22: =H22-I22 | L22: -0.3229 | M22: -0.24606 | N22: -0.24606 | O22: -0.24606 | P22: -0.24606 | Q22: -0.24593 | S22: =L22*J22 | T22: =M22*J22 | U22: =N22*J22 | V22: =O22*J22 | W22: =P22*J22 | X22: =Q22*J22
A23: 109503 | B23: HARRIMAN G3 | C23: 6.9 | D23: 101 | E23: 1100 | F23: 0 | G23: 0 | H23: 0 | I23: 0 | J23: =I23-F23 | K23: =H23-I23 | L23: -0.31305 | M23: -0.23694 | N23: -0.23694 | O23: -0.23694 | P23: -0.23694 | Q23: -0.2368 | S23: =L23*J23 | T23: =M23*J23 | U23: =N23*J23 | V23: =O23*J23 | W23: =P23*J23 | X23: =Q23*J23
A24: 109517 | B24: SEARS HYDRO | C24: 2.4 | D24: 101 | E24: 1100 | F24: 0 | G24: 0 | H24: 0 | I24: 0 | J24: =I24-F24 | K24: =H24-I24 | L24: -0.28244 | M24: -0.20837 | N24: -0.20837 | O24: -0.20837 | P24: -0.20837 | Q24: -0.20825 | S24: =L24*J24 | T24: =M24*J24 | U24: =N24*J24 | V24: =O24*J24 | W24: =P24*J24 | X24: =Q24*J24
A25: 109296 | B25: SEARS WIND_E | C25: 12.5 | D25: 101 | E25: 704 | F25: 0 | G25: 0 | H25: 0 | I25: 0 | J25: =I25-F25 | K25: =H25-I25 | L25: -0.27505 | M25: -0.20142 | N25: -0.20142 | O25: -0.20142 | P25: -0.20142 | Q25: -0.2013 | S25: =L25*J25 | T25: =M25*J25 | U25: =N25*J25 | V25: =O25*J25 | W25: =P25*J25 | X25: =Q25*J25
A26: 109297 | B26: SEARS WIND_W | C26: 12.5 | D26: 101 | E26: 704 | F26: 0 | G26: 0 | H26: 0 | I26: 0 | J26: =I26-F26 | K26: =H26-I26 | L26: -0.27505 | M26: -0.20142 | N26: -0.20142 | O26: -0.20142 | P26: -0.20142 | Q26: -0.2013 | S26: =L26*J26 | T26: =M26*J26 | U26: =N26*J26 | V26: =O26*J26 | W26: =P26*J26 | X26: =Q26*J26
A27: 109403 | B27: DRFLD EAST G | C27: 0.69 | D27: 101 | E27: 704 | F27: 0 | G27: 0 | H27: 0 | I27: 0 | J27: =I27-F27 | K27: =H27-I27 | L27: -0.26758 | M27: -0.1944 | N27: -0.1944 | O27: -0.1944 | P27: -0.1944 | Q27: -0.19427 | S27: =L27*J27 | T27: =M27*J27 | U27: =N27*J27 | V27: =O27*J27 | W27: =P27*J27 | X27: =Q27*J27
... A738: 993001 | B738: SUN_BEAR S~1 | C738: 230 | D738: 101 | E738: 1100 | F738: 83.71 | G738: 0 | H738: 83.71 | I738: 83.71 | J738: =I738-F738 | K738: =H738-I738 | L738: 0.3737 | M738: 0.50516 | N738: 0.50516 | O738: 0.50516 | P738: 0.50516 | Q738: 0.50536 | S738: =L738*J738 | T738: =M738*J738 | U738: =N738*J738 | V738: =O738*J738 | W738: =P738*J738 | X738: =Q738*J738

Sheet 113010 E131 TAP 113005 ADAMS
A1: ****** Plant Redispatch calculator ******* !!!! Please - edit only columns 'Status' & 'Pnew' !!!!!***
A3: Flows
A4: NN | B4: LFCaseName | C4: Monitored Element | I4: Contingency | J4: Limit | K4: FlowInit | L4: FlowRes | M4: FlowChange | N4: Loading
A5: 1 | C5: 113010 E131 TAP 115 113005 ADAMS 115 1 | I5: BO_E131-1 | J5: 357 | K5: 157.2 | L5: ='113010 E131 TAP 113005 ADAMS'!K5+'113010 E131 TAP 113005 ADAMS'!M5 | M5: =N8 | N5: ='113010 E131 TAP 113005 ADAMS'!L5/'113010 E131 TAP 113005 ADAMS'!J5
A8: Dispatch | J8: =SUM(J10:J733) | N8: =SUM(N10:N733)
A9: Bus# | B9: Bus Name | C9: Volt | D9: Area | E9: Zone | F9: Pgen or Pload | G9: PMin Gen | H9: PMax Gen | I9: Pnew | J9: Pdelta | K9: Pavail | L9: Dfax_1 | M9: --- | N9: Impact_1
A10: 993005 | B10: SUN_ADAMS | C10: 115 | D10: 101 | E10: 1100 | F10: 0 | G10: 0 | H10: 0 | I10: 0 | J10: =I10-F10 | K10: =H10-I10 | L10: -0.44015 | N10: =L10*J10
A11: 113101 | B11: DEERFIELD 5G | C11: 13.8 | D11: 101 | E11: 1100 | F11: 0 | G11: 0 | H11: 0 | I11: 0 | J11: =I11-F11 | K11: =H11-I11 | L11: -0.25423 | N11: =L11*J11
A12: 113102 | B12: FIFE BROOK | C12: 13.8 | D12: 101 | E12: 1100 | F12: 9.9 | G12: 0 | H12: 9.9 | I12: 9.9 | J12: =I12-F12 | K12: =H12-I12 | L12: -0.25423 | N12: =L12*J12
A13: 113123 | B13: HOOSAC CLR1 | C13: 0.69 | D13: 101 | E13: 1100 | F13: 0 | G13: 0 | H13: 0 | I13: 0 | J13: =I13-F13 | K13: =H13-I13 | L13: -0.2337 | N13: =L13*J13
A14: 113125 | B14: HOOSAC CLR2 | C14: 0.69 | D14: 101 | E14: 1100 | F14: 0 | G14: 0 | H14: 0 | I14: 0 | J14: =I14-F14 | K14: =H14-I14 | L14: -0.2337 | N14: =L14*J14
A15: 109503 | B15: HARRIMAN G3 | C15: 6.9 | D15: 101 | E15: 1100 | F15: 0 | G15: 0 | H15: 0 | I15: 0 | J15: =I15-F15 | K15: =H15-I15 | L15: -0.22524 | N15: =L15*J15
A16: 109403 | B16: DRFLD EAST G | C16: 0.69 | D16: 101 | E16: 704 | F16: 0 | G16: 0 | H16: 0 | I16: 0 | J16: =I16-F16 | K16: =H16-I16 | L16: -0.21869 | N16: =L16*J16
A17: 109404 | B17: DRFLD WEST G | C17: 0.69 | D17: 101 | E17: 704 | F17: 0 | G17: 0 | H17: 0 | I17: 0 | J17: =I17-F17 | K17: =H17-I17 | L17: -0.21869 | N17: =L17*J17
A18: 109296 | B18: SEARS WIND_E | C18: 12.5 | D18: 101 | E18: 704 | F18: 0 | G18: 0 | H18: 0 | I18: 0 | J18: =I18-F18 | K18: =H18-I18 | L18: -0.21672 | N18: =L18*J18
A19: 109297 | B19: SEARS WIND_W | C19: 12.5 | D19: 101 | E19: 704 | F19: 0 | G19: 0 | H19: 0 | I19: 0 | J19: =I19-F19 | K19: =H19-I19 | L19: -0.21672 | N19: =L19*J19
A20: 109517 | B20: SEARS HYDRO | C20: 2.4 | D20: 101 | E20: 1100 | F20: 0 | G20: 0 | H20: 0 | I20: 0 | J20: =I20-F20 | K20: =H20-I20 | L20: -0.21476 | N20: =L20*J20
A21: 116627 | B21: BERKSHRE WND | C21: 0.57 | D21: 101 | E21: 1374 | F21: 0 | G21: 0 | H21: 0 | I21: 0 | J21: =I21-F21 | K21: =H21-I21 | L21: -0.19515 | N21: =L21*J21
... A733: 993001 | B733: SUN_BEAR S~1 | C733: 230 | D733: 101 | E733: 1100 | F733: 83.71 | G733: 0 | H733: 83.71 | I733: 83.71 | J733: =I733-F733 | K733: =H733-I733 | L733: 0.25681 | N733: =L733*J733

Sheet 115005 NE_E205W_NY 113001 BEAR
A1: ****** Plant Redispatch calculator ******* !!!! Please - edit only columns 'Status' & 'Pnew' !!!!!***
A3: Flows
A4: NN | B4: LFCaseName | C4: Monitored Element | I4: Contingency | J4: Limit | K4: FlowInit | L4: FlowRes | M4: FlowChange | N4: Loading
A5: 1 | C5: 115005 NE_E205W_NY 230 113001 BEAR SWAMP 230 1 | I5: BF_NTHFLD_2T | J5: 519 | K5: 140.4 | L5: ='115005 NE_E205W_NY 113001 BEAR'!K5+'115005 NE_E205W_NY 113001 BEAR'!M5 | M5: =O9 | N5: ='115005 NE_E205W_NY 113001 BEAR'!L5/'115005 NE_E205W_NY 113001 BEAR'!J5
A6: 2 | C6: 115005 NE_E205W_NY 230 113001 BEAR SWAMP 230 1 | I6: LN_312_393 | J6: 519 | K6: 68 | L6: ='115005 NE_E205W_NY 113001 BEAR'!K6+'115005 NE_E205W_NY 113001 BEAR'!M6 | M6: =P9 | N6: ='115005 NE_E205W_NY 113001 BEAR'!L6/'115005 NE_E205W_NY 113001 BEAR'!J6
A9: Dispatch | J9: =SUM(J11:J734) | O9: =SUM(O11:O734) | P9: =SUM(P11:P734)
A10: Bus# | B10: Bus Name | C10: Volt | D10: Area | E10: Zone | F10: Pgen or Pload | G10: PMin Gen | H10: PMax Gen | I10: Pnew | J10: Pdelta | K10: Pavail | L10: Dfax_1 | M10: Dfax_2 | N10: --- | O10: Impact_1 | P10: Impact_2
A11: 113096 | B11: BEARSWAMP 1 | C11: 13.8 | D11: 101 | E11: 1100 | F11: 331.5 | G11: 0 | H11: 331.5 | I11: 331.5 | J11: =I11-F11 | K11: =H11-I11 | L11: -0.27775 | M11: -0.27775 | O11: =L11*J11 | P11: =M11*J11
A12: 113097 | B12: BEARSWAMP 2 | C12: 13.8 | D12: 101 | E12: 1100 | F12: 331.5 | G12: 0 | H12: 331.5 | I12: 331.5 | J12: =I12-F12 | K12: =H12-I12 | L12: -0.27775 | M12: -0.27775 | O12: =L12*J12 | P12: =M12*J12
A13: 993001 | B13: SUN_BEAR S~1 | C13: 230 | D13: 101 | E13: 1100 | F13: 83.71 | G13: 0 | H13: 83.71 | I13: 83.71 | J13: =I13-F13 | K13: =H13-I13 | L13: -0.27775 | M13: -0.27775 | O13: =L13*J13 | P13: =M13*J13
A14: 113100 | B14: DEERFIELD 4G | C14: 2.4 | D14: 101 | E14: 1100 | F14: 0 | G14: 0 | H14: 0 | I14: 0 | J14: =I14-F14 | K14: =H14-I14 | L14: -0.16263 | M14: -0.16263 | O14: =L14*J14 | P14: =M14*J14
A15: 113099 | B15: DEERFIELD 3G | C15: 2.4 | D15: 101 | E15: 1100 | F15: 0 | G15: 0 | H15: 0 | I15: 0 | J15: =I15-F15 | K15: =H15-I15 | L15: -0.15773 | M15: -0.15773 | O15: =L15*J15 | P15: =M15*J15
A16: 113098 | B16: DEERFIELD 2G | C16: 2.4 | D16: 101 | E16: 1100 | F16: 0 | G16: 0 | H16: 0 | I16: 0 | J16: =I16-F16 | K16: =H16-I16 | L16: -0.15159 | M16: -0.15159 | O16: =L16*J16 | P16: =M16*J16
A17: 109504 | B17: HARRIMAN G2 | C17: 6.9 | D17: 101 | E17: 1100 | F17: 13.71 | G17: 0 | H17: 13.71 | I17: 13.71 | J17: =I17-F17 | K17: =H17-I17 | L17: -0.14928 | M17: -0.14928 | O17: =L17*J17 | P17: =M17*J17
A18: 109505 | B18: HARRIMAN G1 | C18: 6.9 | D18: 101 | E18: 1100 | F18: 13.71 | G18: 0 | H18: 13.71 | I18: 13.71 | J18: =I18-F18 | K18: =H18-I18 | L18: -0.14928 | M18: -0.14928 | O18: =L18*J18 | P18: =M18*J18
A19: 113104 | B19: SHERMAN HYD | C19: 2.4 | D19: 101 | E19: 1100 | F19: 0 | G19: 0 | H19: 0 | I19: 0 | J19: =I19-F19 | K19: =H19-I19 | L19: -0.14396 | M19: -0.14396 | O19: =L19*J19 | P19: =M19*J19
A20: 993005 | B20: SUN_ADAMS | C20: 115 | D20: 101 | E20: 1100 | F20: 0 | G20: 0 | H20: 0 | I20: 0 | J20: =I20-F20 | K20: =H20-I20 | L20: -0.13339 | M20: -0.13339 | O20: =L20*J20 | P20: =M20*J20
A21: 109532 | B21: VERNON HY T2 | C21: 13.8 | D21: 101 | E21: 1100 | F21: 0 | G21: 0 | H21: 0 | I21: 0 | J21: =I21-F21 | K21: =H21-I21 | L21: -0.12257 | M21: -0.12257 | O21: =L21*J21 | P21: =M21*J21
A22: 109531 | B22: VERNON HY T1 | C22: 13.8 | D22: 101 | E22: 1100 | F22: 0 | G22: 0 | H22: 0 | I22: 0 | J22: =I22-F22 | K22: =H22-I22 | L22: -0.12257 | M22: -0.12257 | O22: =L22*J22 | P22: =M22*J22
... A734: 911554 | B734: NYNE_OSWG | C734: 345 | D734: 102 | E734: 12 | F734: 120.67 | G734: 0 | H734: 466.67 | I734: 120.67 | J734: =I734-F734 | K734: =H734-I734 | L734: 0.15473 | M734: 0.15473 | O734: =L734*J734 | P734: =M734*J734

Sheet 116023 BERKSHIRE 116312 BERKSHI
A1: ****** Plant Redispatch calculator ******* !!!! Please - edit only columns 'Status' & 'Pnew' !!!!!***
A3: Flows
A4: NN | B4: LFCaseName | C4: Monitored Element | I4: Contingency | J4: Limit | K4: FlowInit | L4: FlowRes | M4: FlowChange | N4: Loading
A5: 1 | C5: 116023 BERKSHIRE 345 116312 BERKSHIRE 115 2 | I5: BF_ADAMS_731 | J5: 533 | K5: 202.9 | L5: ='116023 BERKSHIRE 116312 BERKSHI'!K5+'116023 BERKSHIRE 116312 BERKSHI'!M5 | M5: =S13 | N5: ='116023 BERKSHIRE 116312 BERKSHI'!L5/'116023 BERKSHIRE 116312 BERKSHI'!J5
A6: 2 | C6: 116023 BERKSHIRE 345 116312 BERKSHIRE 115 2 | I6: BF_BEAR_SWP_131 | J6: 533 | K6: 205.6 | L6: ='116023 BERKSHIRE 116312 BERKSHI'!K6+'116023 BERKSHIRE 116312 BERKSHI'!M6 | M6: =T13 | N6: ='116023 BERKSHIRE 116312 BERKSHI'!L6/'116023 BERKSHIRE 116312 BERKSHI'!J6
A7: 3 | C7: 116023 BERKSHIRE 345 116312 BERKSHIRE 115 2 | I7: BF_BEAR_SWP_T31 | J7: 533 | K7: 205.6 | L7: ='116023 BERKSHIRE 116312 BERKSHI'!K7+'116023 BERKSHIRE 116312 BERKSHI'!M7 | M7: =U13 | N7: ='116023 BERKSHIRE 116312 BERKSHI'!L7/'116023 BERKSHIRE 116312 BERKSHI'!J7
A8: 4 | C8: 116023 BERKSHIRE 345 116312 BERKSHIRE 115 2 | I8: BF_FR_BEAR31 | J8: 533 | K8: 222.9 | L8: ='116023 BERKSHIRE 116312 BERKSHI'!K8+'116023 BERKSHIRE 116312 BERKSHI'!M8 | M8: =V13 | N8: ='116023 BERKSHIRE 116312 BERKSHI'!L8/'116023 BERKSHIRE 116312 BERKSHI'!J8
A9: 5 | C9: 116023 BERKSHIRE 345 116312 BERKSHIRE 115 2 | I9: Base Case | J9: 460 | K9: 129.3 | L9: ='116023 BERKSHIRE 116312 BERKSHI'!K9+'116023 BERKSHIRE 116312 BERKSHI'!M9 | M9: =W13 | N9: ='116023 BERKSHIRE 116312 BERKSHI'!L9/'116023 BERKSHIRE 116312 BERKSHI'!J9
A10: 6 | C10: 116023 BERKSHIRE 345 116312 BERKSHIRE 115 2 | I10: NF_312 | J10: 533 | K10: 325.1 | L10: ='116023 BERKSHIRE 116312 BERKSHI'!K10+'116023 BERKSHIRE 116312 BERKSHI'!M10 | M10: =X13 | N10: ='116023 BERKSHIRE 116312 BERKSHI'!L10/'116023 BERKSHIRE 116312 BERKSHI'!J10
A13: Dispatch | J13: =SUM(J15:J738) | S13: =SUM(S15:S738) | T13: =SUM(T15:T738) | U13: =SUM(U15:U738) | V13: =SUM(V15:V738) | W13: =SUM(W15:W738) | X13: =SUM(X15:X738)
A14: Bus# | B14: Bus Name | C14: Volt | D14: Area | E14: Zone | F14: Pgen or Pload | G14: PMin Gen | H14: PMax Gen | I14: Pnew | J14: Pdelta | K14: Pavail | L14: Dfax_1 | M14: Dfax_2 | N14: Dfax_3 | O14: Dfax_4 | P14: Dfax_5 | Q14: Dfax_6 | R14: --- | S14: Impact_1 | T14: Impact_2 | U14: Impact_3 | V14: Impact_4 | W14: Impact_5 | X14: Impact_6
A15: 116618 | B15: ALTRESCO_C1 | C15: 13.8 | D15: 101 | E15: 1373 | F15: 33.65 | G15: 0 | H15: 33.65 | I15: 33.65 | J15: =I15-F15 | K15: =H15-I15 | L15: -0.59306 | M15: -0.5482 | N15: -0.5482 | O15: -0.54712 | P15: -0.49527 | Q15: -0.39 | S15: =L15*J15 | T15: =M15*J15 | U15: =N15*J15 | V15: =O15*J15 | W15: =P15*J15 | X15: =Q15*J15
A16: 116619 | B16: ALTRESCO_C2 | C16: 13.8 | D16: 101 | E16: 1373 | F16: 33.65 | G16: 0 | H16: 33.65 | I16: 33.65 | J16: =I16-F16 | K16: =H16-I16 | L16: -0.59306 | M16: -0.5482 | N16: -0.5482 | O16: -0.54712 | P16: -0.49527 | Q16: -0.39 | S16: =L16*J16 | T16: =M16*J16 | U16: =N16*J16 | V16: =O16*J16 | W16: =P16*J16 | X16: =Q16*J16
A17: 116620 | B17: ALTRESCO_C3 | C17: 13.8 | D17: 101 | E17: 1373 | F17: 31.45 | G17: 0 | H17: 33.65 | I17: 31.45 | J17: =I17-F17 | K17: =H17-I17 | L17: -0.59306 | M17: -0.5482 | N17: -0.5482 | O17: -0.54712 | P17: -0.49527 | Q17: -0.39 | S17: =L17*J17 | T17: =M17*J17 | U17: =N17*J17 | V17: =O17*J17 | W17: =P17*J17 | X17: =Q17*J17
A18: 116621 | B18: ALTRESCO_S4 | C18: 13.8 | D18: 101 | E18: 1373 | F18: 0 | G18: 0 | H18: 0 | I18: 0 | J18: =I18-F18 | K18: =H18-I18 | L18: -0.59306 | M18: -0.5482 | N18: -0.5482 | O18: -0.54712 | P18: -0.49527 | Q18: -0.39 | S18: =L18*J18 | T18: =M18*J18 | U18: =N18*J18 | V18: =O18*J18 | W18: =P18*J18 | X18: =Q18*J18
A19: 116608 | B19: DOREEN JET | C19: 13.2 | D19: 101 | E19: 1374 | F19: 0 | G19: 0 | H19: 0 | I19: 0 | J19: =I19-F19 | K19: =H19-I19 | L19: -0.59305 | M19: -0.54827 | N19: -0.54827 | O19: -0.54719 | P19: -0.49542 | Q19: -0.39013 | S19: =L19*J19 | T19: =M19*J19 | U19: =N19*J19 | V19: =O19*J19 | W19: =P19*J19 | X19: =Q19*J19
A20: 116627 | B20: BERKSHRE WND | C20: 0.57 | D20: 101 | E20: 1374 | F20: 0 | G20: 0 | H20: 0 | I20: 0 | J20: =I20-F20 | K20: =H20-I20 | L20: -0.58022 | M20: -0.51565 | N20: -0.51565 | O20: -0.51447 | P20: -0.44434 | Q20: -0.34563 | S20: =L20*J20 | T20: =M20*J20 | U20: =N20*J20 | V20: =O20*J20 | W20: =P20*J20 | X20: =Q20*J20
A21: 996336 | B21: SUN BAT_PA~2 | C21: 115 | D21: 101 | E21: 1370 | F21: 0 | G21: 0 | H21: 0 | I21: 0 | J21: =I21-F21 | K21: =H21-I21 | L21: -0.58022 | M21: -0.51565 | N21: -0.51565 | O21: -0.51447 | P21: -0.44434 | Q21: -0.34563 | S21: =L21*J21 | T21: =M21*J21 | U21: =N21*J21 | V21: =O21*J21 | W21: =P21*J21 | X21: =Q21*J21
A22: 996625 | B22: SUN BAT_PA~1 | C22: 23 | D22: 101 | E22: 1372 | F22: 0 | G22: 0 | H22: 0 | I22: 0 | J22: =I22-F22 | K22: =H22-I22 | L22: -0.58022 | M22: -0.51565 | N22: -0.51565 | O22: -0.51447 | P22: -0.44434 | Q22: -0.34563 | S22: =L22*J22 | T22: =M22*J22 | U22: =N22*J22 | V22: =O22*J22 | W22: =P22*J22 | X22: =Q22*J22
A23: 999312 | B23: Strata_Ber~1 | C23: 115 | D23: 101 | E23: 1370 | F23: 0 | G23: 0 | H23: 0 | I23: -100 | J23: =I23-F23 | K23: =H23-I23 | L23: -0.57151 | M23: -0.54425 | N23: -0.54425 | O23: -0.54325 | P23: -0.50508 | Q23: -0.40209 | S23: =L23*J23 | T23: =M23*J23 | U23: =N23*J23 | V23: =O23*J23 | W23: =P23*J23 | X23: =Q23*J23
A24: 993005 | B24: SUN_ADAMS | C24: 115 | D24: 101 | E24: 1100 | F24: 0 | G24: 0 | H24: 0 | I24: 0 | J24: =I24-F24 | K24: =H24-I24 | L24: -0.5205 | M24: -0.36428 | N24: -0.36428 | O24: -0.36269 | P24: -0.20751 | Q24: -0.13937 | S24: =L24*J24 | T24: =M24*J24 | U24: =N24*J24 | V24: =O24*J24 | W24: =P24*J24 | X24: =Q24*J24
A25: 116638 | B25: WOODLAND JET | C25: 13.2 | D25: 101 | E25: 1374 | F25: 0 | G25: 0 | H25: 0 | I25: 0 | J25: =I25-F25 | K25: =H25-I25 | L25: -0.50393 | M25: -0.46571 | N25: -0.46571 | O25: -0.46476 | P25: -0.42043 | Q25: -0.3321 | S25: =L25*J25 | T25: =M25*J25 | U25: =N25*J25 | V25: =O25*J25 | W25: =P25*J25 | X25: =Q25*J25
A26: 113061 | B26: PLEASANT-NEP | C26: 23 | D26: 101 | E26: 1100 | F26: 0 | G26: 0 | H26: 0 | I26: 0 | J26: =I26-F26 | K26: =H26-I26 | L26: -0.45126 | M26: -0.41694 | N26: -0.41694 | O26: -0.41607 | P26: -0.37615 | Q26: -0.29783 | S26: =L26*J26 | T26: =M26*J26 | U26: =N26*J26 | V26: =O26*J26 | W26: =P26*J26 | X26: =Q26*J26
... A738: 911531 | B738: NYNE_GILB | C738: 345 | D738: 102 | E738: 12 | F738: 120.67 | G738: 0 | H738: 466.67 | I738: 120.67 | J738: =I738-F738 | K738: =H738-I738 | L738: 0.05641 | M738: 0.04906 | N738: 0.04906 | O738: 0.05086 | P738: 0.05013 | Q738: 0.14798 | S738: =L738*J738 | T738: =M738*J738 | U738: =N738*J738 | V738: =O738*J738 | W738: =P738*J738 | X738: =Q738*J738

Sheet 116034 NE_393_NY 116023 BERKSHI
A1: ****** Plant Redispatch calculator ******* !!!! Please - edit only columns 'Status' & 'Pnew' !!!!!***
A3: Flows
A4: NN | B4: LFCaseName | C4: Monitored Element | I4: Contingency | J4: Limit | K4: FlowInit | L4: FlowRes | M4: FlowChange | N4: Loading
A5: 1 | C5: 116034 NE_393_NY 345 116023 BERKSHIRE 345 1 | I5: BF_SEBRK_941 | J5: 1697 | K5: 1131.8 | L5: ='116034 NE_393_NY 116023 BERKSHI'!K5+'116034 NE_393_NY 116023 BERKSHI'!M5 | M5: =S13 | N5: ='116034 NE_393_NY 116023 BERKSHI'!L5/'116034 NE_393_NY 116023 BERKSHI'!J5
A6: 2 | C6: 116034 NE_393_NY 345 116023 BERKSHIRE 345 1 | I6: GN_SBRK | J6: 1697 | K6: 1153.9 | L6: ='116034 NE_393_NY 116023 BERKSHI'!K6+'116034 NE_393_NY 116023 BERKSHI'!M6 | M6: =T13 | N6: ='116034 NE_393_NY 116023 BERKSHI'!L6/'116034 NE_393_NY 116023 BERKSHI'!J6
A7: 3 | C7: 116034 NE_393_NY 345 116023 BERKSHIRE 345 1 | I7: TF_SBRK_GSU | J7: 1697 | K7: 1137.3 | L7: ='116034 NE_393_NY 116023 BERKSHI'!K7+'116034 NE_393_NY 116023 BERKSHI'!M7 | M7: =U13 | N7: ='116034 NE_393_NY 116023 BERKSHI'!L7/'116034 NE_393_NY 116023 BERKSHI'!J7
A8: 4 | C8: 116034 NE_393_NY 345 116023 BERKSHIRE 345 1 | I8: GN_MIL3 | J8: 1697 | K8: 1045.2 | L8: ='116034 NE_393_NY 116023 BERKSHI'!K8+'116034 NE_393_NY 116023 BERKSHI'!M8 | M8: =V13 | N8: ='116034 NE_393_NY 116023 BERKSHI'!L8/'116034 NE_393_NY 116023 BERKSHI'!J8
A9: 5 | C9: 116034 NE_393_NY 345 116023 BERKSHIRE 345 1 | I9: Base Case | J9: 1463 | K9: 750.8 | L9: ='116034 NE_393_NY 116023 BERKSHI'!K9+'116034 NE_393_NY 116023 BERKSHI'!M9 | M9: =W13 | N9: ='116034 NE_393_NY 116023 BERKSHI'!L9/'116034 NE_393_NY 116023 BERKSHI'!J9
A10: 6 | C10: 116034 NE_393_NY 345 116023 BERKSHIRE 345 1 | I10: BF_SEBRK_169 | J10: 1697 | K10: 1135.2 | L10: ='116034 NE_393_NY 116023 BERKSHI'!K10+'116034 NE_393_NY 116023 BERKSHI'!M10 | M10: =X13 | N10: ='116034 NE_393_NY 116023 BERKSHI'!L10/'116034 NE_393_NY 116023 BERKSHI'!J10
A13: Dispatch | J13: =SUM(J15:J738) | S13: =SUM(S15:S738) | T13: =SUM(T15:T738) | U13: =SUM(U15:U738) | V13: =SUM(V15:V738) | W13: =SUM(W15:W738) | X13: =SUM(X15:X738)
A14: Bus# | B14: Bus Name | C14: Volt | D14: Area | E14: Zone | F14: Pgen or Pload | G14: PMin Gen | H14: PMax Gen | I14: Pnew | J14: Pdelta | K14: Pavail | L14: Dfax_1 | M14: Dfax_2 | N14: Dfax_3 | O14: Dfax_4 | P14: Dfax_5 | Q14: Dfax_6 | R14: --- | S14: Impact_1 | T14: Impact_2 | U14: Impact_3 | V14: Impact_4 | W14: Impact_5 | X14: Impact_6
A15: 999312 | B15: Strata_Ber~1 | C15: 115 | D15: 101 | E15: 1370 | F15: 0 | G15: 0 | H15: 0 | I15: -100 | J15: =I15-F15 | K15: =H15-I15 | L15: -0.18132 | M15: -0.18123 | N15: -0.18123 | O15: -0.18123 | P15: -0.18123 | Q15: -0.18118 | S15: =L15*J15 | T15: =M15*J15 | U15: =N15*J15 | V15: =O15*J15 | W15: =P15*J15 | X15: =Q15*J15
A16: 116608 | B16: DOREEN JET | C16: 13.2 | D16: 101 | E16: 1374 | F16: 0 | G16: 0 | H16: 0 | I16: 0 | J16: =I16-F16 | K16: =H16-I16 | L16: -0.16441 | M16: -0.16433 | N16: -0.16433 | O16: -0.16433 | P16: -0.16433 | Q16: -0.16428 | S16: =L16*J16 | T16: =M16*J16 | U16: =N16*J16 | V16: =O16*J16 | W16: =P16*J16 | X16: =Q16*J16
A17: 116618 | B17: ALTRESCO_C1 | C17: 13.8 | D17: 101 | E17: 1373 | F17: 33.65 | G17: 0 | H17: 33.65 | I17: 33.65 | J17: =I17-F17 | K17: =H17-I17 | L17: -0.16431 | M17: -0.16423 | N17: -0.16423 | O17: -0.16423 | P17: -0.16423 | Q17: -0.16418 | S17: =L17*J17 | T17: =M17*J17 | U17: =N17*J17 | V17: =O17*J17 | W17: =P17*J17 | X17: =Q17*J17
A18: 116619 | B18: ALTRESCO_C2 | C18: 13.8 | D18: 101 | E18: 1373 | F18: 33.65 | G18: 0 | H18: 33.65 | I18: 33.65 | J18: =I18-F18 | K18: =H18-I18 | L18: -0.16431 | M18: -0.16423 | N18: -0.16423 | O18: -0.16423 | P18: -0.16423 | Q18: -0.16418 | S18: =L18*J18 | T18: =M18*J18 | U18: =N18*J18 | V18: =O18*J18 | W18: =P18*J18 | X18: =Q18*J18
A19: 116620 | B19: ALTRESCO_C3 | C19: 13.8 | D19: 101 | E19: 1373 | F19: 31.45 | G19: 0 | H19: 33.65 | I19: 31.45 | J19: =I19-F19 | K19: =H19-I19 | L19: -0.16431 | M19: -0.16423 | N19: -0.16423 | O19: -0.16423 | P19: -0.16423 | Q19: -0.16418 | S19: =L19*J19 | T19: =M19*J19 | U19: =N19*J19 | V19: =O19*J19 | W19: =P19*J19 | X19: =Q19*J19
A20: 116621 | B20: ALTRESCO_S4 | C20: 13.8 | D20: 101 | E20: 1373 | F20: 0 | G20: 0 | H20: 0 | I20: 0 | J20: =I20-F20 | K20: =H20-I20 | L20: -0.16431 | M20: -0.16423 | N20: -0.16423 | O20: -0.16423 | P20: -0.16423 | Q20: -0.16418 | S20: =L20*J20 | T20: =M20*J20 | U20: =N20*J20 | V20: =O20*J20 | W20: =P20*J20 | X20: =Q20*J20
A21: 116638 | B21: WOODLAND JET | C21: 13.2 | D21: 101 | E21: 1374 | F21: 0 | G21: 0 | H21: 0 | I21: 0 | J21: =I21-F21 | K21: =H21-I21 | L21: -0.14273 | M21: -0.14266 | N21: -0.14266 | O21: -0.14266 | P21: -0.14266 | Q21: -0.14261 | S21: =L21*J21 | T21: =M21*J21 | U21: =N21*J21 | V21: =O21*J21 | W21: =P21*J21 | X21: =Q21*J21
A22: 116627 | B22: BERKSHRE WND | C22: 0.57 | D22: 101 | E22: 1374 | F22: 0 | G22: 0 | H22: 0 | I22: 0 | J22: =I22-F22 | K22: =H22-I22 | L22: -0.13404 | M22: -0.13396 | N22: -0.13396 | O22: -0.13396 | P22: -0.13396 | Q22: -0.13391 | S22: =L22*J22 | T22: =M22*J22 | U22: =N22*J22 | V22: =O22*J22 | W22: =P22*J22 | X22: =Q22*J22
A23: 996336 | B23: SUN BAT_PA~2 | C23: 115 | D23: 101 | E23: 1370 | F23: 0 | G23: 0 | H23: 0 | I23: 0 | J23: =I23-F23 | K23: =H23-I23 | L23: -0.13404 | M23: -0.13396 | N23: -0.13396 | O23: -0.13396 | P23: -0.13396 | Q23: -0.13391 | S23: =L23*J23 | T23: =M23*J23 | U23: =N23*J23 | V23: =O23*J23 | W23: =P23*J23 | X23: =Q23*J23
A24: 996625 | B24: SUN BAT_PA~1 | C24: 23 | D24: 101 | E24: 1372 | F24: 0 | G24: 0 | H24: 0 | I24: 0 | J24: =I24-F24 | K24: =H24-I24 | L24: -0.13404 | M24: -0.13396 | N24: -0.13396 | O24: -0.13396 | P24: -0.13396 | Q24: -0.13391 | S24: =L24*J24 | T24: =M24*J24 | U24: =N24*J24 | V24: =O24*J24 | W24: =P24*J24 | X24: =Q24*J24
A25: 116414 | B25: NORTHFIELD 4 | C25: 13.8 | D25: 101 | E25: 1373 | F25: 292 | G25: 0 | H25: 292 | I25: 292 | J25: =I25-F25 | K25: =H25-I25 | L25: -0.13246 | M25: -0.13228 | N25: -0.13228 | O25: -0.13228 | P25: -0.13228 | Q25: -0.13224 | S25: =L25*J25 | T25: =M25*J25 | U25: =N25*J25 | V25: =O25*J25 | W25: =P25*J25 | X25: =Q25*J25
A26: 116413 | B26: NORTHFIELD 3 | C26: 13.8 | D26: 101 | E26: 1373 | F26: 292 | G26: 0 | H26: 292 | I26: 292 | J26: =I26-F26 | K26: =H26-I26 | L26: -0.13246 | M26: -0.13228 | N26: -0.13228 | O26: -0.13228 | P26: -0.13228 | Q26: -0.13224 | S26: =L26*J26 | T26: =M26*J26 | U26: =N26*J26 | V26: =O26*J26 | W26: =P26*J26 | X26: =Q26*J26
... A738: 911531 | B738: NYNE_GILB | C738: 345 | D738: 102 | E738: 12 | F738: 120.67 | G738: 0 | H738: 466.67 | I738: 120.67 | J738: =I738-F738 | K738: =H738-I738 | L738: 0.35778 | M738: 0.35783 | N738: 0.35783 | O738: 0.35783 | P738: 0.35783 | Q738: 0.35788 | S738: =L738*J738 | T738: =M738*J738 | U738: =N738*J738 | V738: =O738*J738 | W738: =P738*J738 | X738: =Q738*J738

Sheet 116312 BERKSHIRE 999312 Strata
A1: ****** Plant Redispatch calculator ******* !!!! Please - edit only columns 'Status' & 'Pnew' !!!!!***
A3: Flows
A4: NN | B4: LFCaseName | C4: Monitored Element | I4: Contingency | J4: Limit | K4: FlowInit | L4: FlowRes | M4: FlowChange | N4: Loading
A5: 1 | C5: 116312 BERKSHIRE 115 999312 Strata_Ber~1 115 1 | I5: NF_1231-1_2 | J5: 101 | K5: 54.5 | L5: ='116312 BERKSHIRE 999312 Strata'!K5+'116312 BERKSHIRE 999312 Strata'!M5 | M5: =R12 | N5: ='116312 BERKSHIRE 999312 Strata'!L5/'116312 BERKSHIRE 999312 Strata'!J5
A6: 2 | C6: 116312 BERKSHIRE 115 999312 Strata_Ber~1 115 1 | I6: BF_HARRMN_10 | J6: 101 | K6: 53.9 | L6: ='116312 BERKSHIRE 999312 Strata'!K6+'116312 BERKSHIRE 999312 Strata'!M6 | M6: =S12 | N6: ='116312 BERKSHIRE 999312 Strata'!L6/'116312 BERKSHIRE 999312 Strata'!J6
A7: 3 | C7: 116312 BERKSHIRE 115 999312 Strata_Ber~1 115 1 | I7: BS_HARRIMAN2 | J7: 101 | K7: 53.9 | L7: ='116312 BERKSHIRE 999312 Strata'!K7+'116312 BERKSHIRE 999312 Strata'!M7 | M7: =T12 | N7: ='116312 BERKSHIRE 999312 Strata'!L7/'116312 BERKSHIRE 999312 Strata'!J7
A8: 4 | C8: 116312 BERKSHIRE 115 999312 Strata_Ber~1 115 1 | I8: BF_HARRMN_77 | J8: 101 | K8: 53.8 | L8: ='116312 BERKSHIRE 999312 Strata'!K8+'116312 BERKSHIRE 999312 Strata'!M8 | M8: =U12 | N8: ='116312 BERKSHIRE 999312 Strata'!L8/'116312 BERKSHIRE 999312 Strata'!J8
A9: 5 | C9: 116312 BERKSHIRE 115 999312 Strata_Ber~1 115 1 | I9: NF_312 | J9: 101 | K9: 81.8 | L9: ='116312 BERKSHIRE 999312 Strata'!K9+'116312 BERKSHIRE 999312 Strata'!M9 | M9: =V12 | N9: ='116312 BERKSHIRE 999312 Strata'!L9/'116312 BERKSHIRE 999312 Strata'!J9
A12: Dispatch | J12: =SUM(J14:J737) | R12: =SUM(R14:R737) | S12: =SUM(S14:S737) | T12: =SUM(T14:T737) | U12: =SUM(U14:U737) | V12: =SUM(V14:V737)
A13: Bus# | B13: Bus Name | C13: Volt | D13: Area | E13: Zone | F13: Pgen or Pload | G13: PMin Gen | H13: PMax Gen | I13: Pnew | J13: Pdelta | K13: Pavail | L13: Dfax_1 | M13: Dfax_2 | N13: Dfax_3 | O13: Dfax_4 | P13: Dfax_5 | Q13: --- | R13: Impact_1 | S13: Impact_2 | T13: Impact_3 | U13: Impact_4 | V13: Impact_5
A14: 999312 | B14: Strata_Ber~1 | C14: 115 | D14: 101 | E14: 1370 | F14: 0 | G14: 0 | H14: 0 | I14: -100 | J14: =I14-F14 | K14: =H14-I14 | L14: -0.65038 | M14: -0.36565 | N14: -0.36565 | O14: -0.36565 | P14: -0.32888 | R14: =L14*J14 | S14: =M14*J14 | T14: =N14*J14 | U14: =O14*J14 | V14: =P14*J14
A15: 996284 | B15: SUN_CUMBER~1 | C15: 115 | D15: 101 | E15: 1370 | F15: 0 | G15: 0 | H15: 0 | I15: 0 | J15: =I15-F15 | K15: =H15-I15 | L15: -0.29962 | M15: -0.19928 | N15: -0.19928 | O15: -0.19928 | P15: -0.15223 | R15: =L15*J15 | S15: =M15*J15 | T15: =N15*J15 | U15: =O15*J15 | V15: =P15*J15
A16: 116568 | B16: TILSON-1044 | C16: 13.8 | D16: 101 | E16: 1372 | F16: 0 | G16: 0 | H16: 0 | I16: 0 | J16: =I16-F16 | K16: =H16-I16 | L16: -0.25716 | M16: -0.17914 | N16: -0.17914 | O16: -0.17914 | P16: -0.13085 | R16: =L16*J16 | S16: =M16*J16 | T16: =N16*J16 | U16: =O16*J16 | V16: =P16*J16
A17: 116578 | B17: TURNERS FALS | C17: 2.4 | D17: 101 | E17: 1374 | F17: 0 | G17: 0 | H17: 0 | I17: 0 | J17: =I17-F17 | K17: =H17-I17 | L17: -0.25716 | M17: -0.17914 | N17: -0.17914 | O17: -0.17914 | P17: -0.13085 | R17: =L17*J17 | S17: =M17*J17 | T17: =N17*J17 | U17: =O17*J17 | V17: =P17*J17
A18: 116579 | B18: CABOT HYDRO | C18: 13.8 | D18: 101 | E18: 1373 | F18: 64.66 | G18: 0 | H18: 64.66 | I18: 64.66 | J18: =I18-F18 | K18: =H18-I18 | L18: -0.25716 | M18: -0.17914 | N18: -0.17914 | O18: -0.17914 | P18: -0.13085 | R18: =L18*J18 | S18: =M18*J18 | T18: =N18*J18 | U18: =O18*J18 | V18: =P18*J18
A19: 996270 | B19: SUN BAT_TI~1 | C19: 115 | D19: 101 | E19: 1370 | F19: 0 | G19: 0 | H19: 0 | I19: 0 | J19: =I19-F19 | K19: =H19-I19 | L19: -0.25716 | M19: -0.17914 | N19: -0.17914 | O19: -0.17914 | P19: -0.13085 | R19: =L19*J19 | S19: =M19*J19 | T19: =N19*J19 | U19: =O19*J19 | V19: =P19*J19
A20: 113085 | B20: WENDELL DEP | C20: 13.8 | D20: 101 | E20: 1100 | F20: 0 | G20: 0 | H20: 0 | I20: 0 | J20: =I20-F20 | K20: =H20-I20 | L20: -0.1081 | M20: -0.07924 | N20: -0.07924 | O20: -0.07924 | P20: -0.06013 | R20: =L20*J20 | S20: =M20*J20 | T20: =N20*J20 | U20: =O20*J20 | V20: =P20*J20
A21: 993015 | B21: SUN_WENDEL~1 | C21: 115 | D21: 101 | E21: 1100 | F21: 0 | G21: 0 | H21: 0 | I21: 0 | J21: =I21-F21 | K21: =H21-I21 | L21: -0.1081 | M21: -0.07924 | N21: -0.07924 | O21: -0.07924 | P21: -0.06013 | R21: =L21*J21 | S21: =M21*J21 | T21: =N21*J21 | U21: =O21*J21 | V21: =P21*J21
A22: 113104 | B22: SHERMAN HYD | C22: 2.4 | D22: 101 | E22: 1100 | F22: 0 | G22: 0 | H22: 0 | I22: 0 | J22: =I22-F22 | K22: =H22-I22 | L22: -0.09796 | M22: -0.17879 | N22: -0.17879 | O22: 0.01465 | P22: -0.04166 | R22: =L22*J22 | S22: =M22*J22 | T22: =N22*J22 | U22: =O22*J22 | V22: =P22*J22
A23: 109505 | B23: HARRIMAN G1 | C23: 6.9 | D23: 101 | E23: 1100 | F23: 13.71 | G23: 0 | H23: 13.71 | I23: 13.71 | J23: =I23-F23 | K23: =H23-I23 | L23: -0.08366 | M23: -0.11187 | N23: -0.11187 | O23: -0.11187 | P23: -0.03365 | R23: =L23*J23 | S23: =M23*J23 | T23: =N23*J23 | U23: =O23*J23 | V23: =P23*J23
A24: 109504 | B24: HARRIMAN G2 | C24: 6.9 | D24: 101 | E24: 1100 | F24: 13.71 | G24: 0 | H24: 13.71 | I24: 13.71 | J24: =I24-F24 | K24: =H24-I24 | L24: -0.08366 | M24: -0.11187 | N24: -0.11187 | O24: -0.11187 | P24: -0.03365 | R24: =L24*J24 | S24: =M24*J24 | T24: =N24*J24 | U24: =O24*J24 | V24: =P24*J24
A25: 113011 | B25: BAT_BarreB~1 | C25: 115 | D25: 101 | E25: 1100 | F25: 0 | G25: 0 | H25: 0 | I25: 0 | J25: =I25-F25 | K25: =H25-I25 | L25: -0.05306 | M25: -0.06832 | N25: -0.06832 | O25: -0.06832 | P25: -0.02239 | R25: =L25*J25 | S25: =M25*J25 | T25: =N25*J25 | U25: =O25*J25 | V25: =P25*J25
... A737: 116608 | B737: DOREEN JET | C737: 13.2 | D737: 101 | E737: 1374 | F737: 0 | G737: 0 | H737: 0 | I737: 0 | J737: =I737-F737 | K737: =H737-I737 | L737: 0.14622 | M737: 0.08213 | N737: 0.08213 | O737: 0.08213 | P737: 0.10809 | R737: =L737*J737 | S737: =M737*J737 | T737: =N737*J737 | U737: =O737*J737 | V737: =P737*J737

Sheet 116312 BERKSHIRE  999312 S
A1: ****** Plant Redispatch calculator ******* !!!! Please - edit only columns 'Status' & 'Pnew' !!!!!***
A3: Flows
A4: NN | B4: LFCaseName | C4: Monitored Element | I4: Contingency | J4: Limit | K4: FlowInit | L4: FlowRes | M4: FlowChange | N4: Loading
A5: 1 | C5: 116312 BERKSHIRE 115 999312 Strata_Ber~1 115 2 | I5: NF_1242-1_2 | J5: 101 | K5: 54.5 | L5: ='116312 BERKSHIRE 999312 S'!K5+'116312 BERKSHIRE 999312 S'!M5 | M5: =R12 | N5: ='116312 BERKSHIRE 999312 S'!L5/'116312 BERKSHIRE 999312 S'!J5
A6: 2 | C6: 116312 BERKSHIRE 115 999312 Strata_Ber~1 115 2 | I6: BF_HARRMN_10 | J6: 101 | K6: 54 | L6: ='116312 BERKSHIRE 999312 S'!K6+'116312 BERKSHIRE 999312 S'!M6 | M6: =S12 | N6: ='116312 BERKSHIRE 999312 S'!L6/'116312 BERKSHIRE 999312 S'!J6
A7: 3 | C7: 116312 BERKSHIRE 115 999312 Strata_Ber~1 115 2 | I7: BS_HARRIMAN2 | J7: 101 | K7: 54 | L7: ='116312 BERKSHIRE 999312 S'!K7+'116312 BERKSHIRE 999312 S'!M7 | M7: =T12 | N7: ='116312 BERKSHIRE 999312 S'!L7/'116312 BERKSHIRE 999312 S'!J7
A8: 4 | C8: 116312 BERKSHIRE 115 999312 Strata_Ber~1 115 2 | I8: BF_HARRMN_77 | J8: 101 | K8: 54 | L8: ='116312 BERKSHIRE 999312 S'!K8+'116312 BERKSHIRE 999312 S'!M8 | M8: =U12 | N8: ='116312 BERKSHIRE 999312 S'!L8/'116312 BERKSHIRE 999312 S'!J8
A9: 5 | C9: 116312 BERKSHIRE 115 999312 Strata_Ber~1 115 2 | I9: NF_312 | J9: 101 | K9: 82 | L9: ='116312 BERKSHIRE 999312 S'!K9+'116312 BERKSHIRE 999312 S'!M9 | M9: =V12 | N9: ='116312 BERKSHIRE 999312 S'!L9/'116312 BERKSHIRE 999312 S'!J9
A12: Dispatch | J12: =SUM(J14:J737) | R12: =SUM(R14:R737) | S12: =SUM(S14:S737) | T12: =SUM(T14:T737) | U12: =SUM(U14:U737) | V12: =SUM(V14:V737)
A13: Bus# | B13: Bus Name | C13: Volt | D13: Area | E13: Zone | F13: Pgen or Pload | G13: PMin Gen | H13: PMax Gen | I13: Pnew | J13: Pdelta | K13: Pavail | L13: Dfax_1 | M13: Dfax_2 | N13: Dfax_3 | O13: Dfax_4 | P13: Dfax_5 | Q13: --- | R13: Impact_1 | S13: Impact_2 | T13: Impact_3 | U13: Impact_4 | V13: Impact_5
A14: 999312 | B14: Strata_Ber~1 | C14: 115 | D14: 101 | E14: 1370 | F14: 0 | G14: 0 | H14: 0 | I14: -100 | J14: =I14-F14 | K14: =H14-I14 | L14: -0.65038 | M14: -0.36565 | N14: -0.36565 | O14: -0.36565 | P14: -0.32888 | R14: =L14*J14 | S14: =M14*J14 | T14: =N14*J14 | U14: =O14*J14 | V14: =P14*J14
A15: 996284 | B15: SUN_CUMBER~1 | C15: 115 | D15: 101 | E15: 1370 | F15: 0 | G15: 0 | H15: 0 | I15: 0 | J15: =I15-F15 | K15: =H15-I15 | L15: -0.29962 | M15: -0.19928 | N15: -0.19928 | O15: -0.19928 | P15: -0.15223 | R15: =L15*J15 | S15: =M15*J15 | T15: =N15*J15 | U15: =O15*J15 | V15: =P15*J15
A16: 116568 | B16: TILSON-1044 | C16: 13.8 | D16: 101 | E16: 1372 | F16: 0 | G16: 0 | H16: 0 | I16: 0 | J16: =I16-F16 | K16: =H16-I16 | L16: -0.25716 | M16: -0.17914 | N16: -0.17914 | O16: -0.17914 | P16: -0.13085 | R16: =L16*J16 | S16: =M16*J16 | T16: =N16*J16 | U16: =O16*J16 | V16: =P16*J16
A17: 116578 | B17: TURNERS FALS | C17: 2.4 | D17: 101 | E17: 1374 | F17: 0 | G17: 0 | H17: 0 | I17: 0 | J17: =I17-F17 | K17: =H17-I17 | L17: -0.25716 | M17: -0.17914 | N17: -0.17914 | O17: -0.17914 | P17: -0.13085 | R17: =L17*J17 | S17: =M17*J17 | T17: =N17*J17 | U17: =O17*J17 | V17: =P17*J17
A18: 116579 | B18: CABOT HYDRO | C18: 13.8 | D18: 101 | E18: 1373 | F18: 64.66 | G18: 0 | H18: 64.66 | I18: 64.66 | J18: =I18-F18 | K18: =H18-I18 | L18: -0.25716 | M18: -0.17914 | N18: -0.17914 | O18: -0.17914 | P18: -0.13085 | R18: =L18*J18 | S18: =M18*J18 | T18: =N18*J18 | U18: =O18*J18 | V18: =P18*J18
A19: 996270 | B19: SUN BAT_TI~1 | C19: 115 | D19: 101 | E19: 1370 | F19: 0 | G19: 0 | H19: 0 | I19: 0 | J19: =I19-F19 | K19: =H19-I19 | L19: -0.25716 | M19: -0.17914 | N19: -0.17914 | O19: -0.17914 | P19: -0.13085 | R19: =L19*J19 | S19: =M19*J19 | T19: =N19*J19 | U19: =O19*J19 | V19: =P19*J19
A20: 113085 | B20: WENDELL DEP | C20: 13.8 | D20: 101 | E20: 1100 | F20: 0 | G20: 0 | H20: 0 | I20: 0 | J20: =I20-F20 | K20: =H20-I20 | L20: -0.1081 | M20: -0.07924 | N20: -0.07924 | O20: -0.07924 | P20: -0.06013 | R20: =L20*J20 | S20: =M20*J20 | T20: =N20*J20 | U20: =O20*J20 | V20: =P20*J20
A21: 993015 | B21: SUN_WENDEL~1 | C21: 115 | D21: 101 | E21: 1100 | F21: 0 | G21: 0 | H21: 0 | I21: 0 | J21: =I21-F21 | K21: =H21-I21 | L21: -0.1081 | M21: -0.07924 | N21: -0.07924 | O21: -0.07924 | P21: -0.06013 | R21: =L21*J21 | S21: =M21*J21 | T21: =N21*J21 | U21: =O21*J21 | V21: =P21*J21
A22: 113104 | B22: SHERMAN HYD | C22: 2.4 | D22: 101 | E22: 1100 | F22: 0 | G22: 0 | H22: 0 | I22: 0 | J22: =I22-F22 | K22: =H22-I22 | L22: -0.09796 | M22: -0.17879 | N22: -0.17879 | O22: 0.01465 | P22: -0.04166 | R22: =L22*J22 | S22: =M22*J22 | T22: =N22*J22 | U22: =O22*J22 | V22: =P22*J22
A23: 109505 | B23: HARRIMAN G1 | C23: 6.9 | D23: 101 | E23: 1100 | F23: 13.71 | G23: 0 | H23: 13.71 | I23: 13.71 | J23: =I23-F23 | K23: =H23-I23 | L23: -0.08366 | M23: -0.11187 | N23: -0.11187 | O23: -0.11187 | P23: -0.03365 | R23: =L23*J23 | S23: =M23*J23 | T23: =N23*J23 | U23: =O23*J23 | V23: =P23*J23
A24: 109504 | B24: HARRIMAN G2 | C24: 6.9 | D24: 101 | E24: 1100 | F24: 13.71 | G24: 0 | H24: 13.71 | I24: 13.71 | J24: =I24-F24 | K24: =H24-I24 | L24: -0.08366 | M24: -0.11187 | N24: -0.11187 | O24: -0.11187 | P24: -0.03365 | R24: =L24*J24 | S24: =M24*J24 | T24: =N24*J24 | U24: =O24*J24 | V24: =P24*J24
A25: 113011 | B25: BAT_BarreB~1 | C25: 115 | D25: 101 | E25: 1100 | F25: 0 | G25: 0 | H25: 0 | I25: 0 | J25: =I25-F25 | K25: =H25-I25 | L25: -0.05306 | M25: -0.06832 | N25: -0.06832 | O25: -0.06832 | P25: -0.02239 | R25: =L25*J25 | S25: =M25*J25 | T25: =N25*J25 | U25: =O25*J25 | V25: =P25*J25
... A737: 116608 | B737: DOREEN JET | C737: 13.2 | D737: 101 | E737: 1374 | F737: 0 | G737: 0 | H737: 0 | I737: 0 | J737: =I737-F737 | K737: =H737-I737 | L737: 0.14622 | M737: 0.08213 | N737: 0.08213 | O737: 0.08213 | P737: 0.10809 | R737: =L737*J737 | S737: =M737*J737 | T737: =N737*J737 | U737: =O737*J737 | V737: =P737*J737

Sheet 119363 NORWALK_J 119480 NORWALK
A1: ****** Plant Redispatch calculator ******* !!!! Please - edit only columns 'Status' & 'Pnew' !!!!!***
A3: Flows
A4: NN | B4: LFCaseName | C4: Monitored Element | I4: Contingency | J4: Limit | K4: FlowInit | L4: FlowRes | M4: FlowChange | N4: Loading
A5: 1 | C5: 119363 NORWALK_J 345 119480 NORWALK 345 1 | I5: DC_3827_1208_NPCC | J5: 1644 | K5: -11.7 | L5: ='119363 NORWALK_J 119480 NORWALK'!K5+'119363 NORWALK_J 119480 NORWALK'!M5 | M5: =R12 | N5: ='119363 NORWALK_J 119480 NORWALK'!L5/'119363 NORWALK_J 119480 NORWALK'!J5
A6: 2 | C6: 119363 NORWALK_J 345 119480 NORWALK 345 1 | I6: DC_3827_1610_NPCC | J6: 1644 | K6: -20.5 | L6: ='119363 NORWALK_J 119480 NORWALK'!K6+'119363 NORWALK_J 119480 NORWALK'!M6 | M6: =S12 | N6: ='119363 NORWALK_J 119480 NORWALK'!L6/'119363 NORWALK_J 119480 NORWALK'!J6
A7: 3 | C7: 119363 NORWALK_J 345 119480 NORWALK 345 1 | I7: LN_3827 | J7: 1644 | K7: -19.4 | L7: ='119363 NORWALK_J 119480 NORWALK'!K7+'119363 NORWALK_J 119480 NORWALK'!M7 | M7: =T12 | N7: ='119363 NORWALK_J 119480 NORWALK'!L7/'119363 NORWALK_J 119480 NORWALK'!J7
A8: 4 | C8: 119363 NORWALK_J 345 119480 NORWALK 345 1 | I8: BF_BESECK_09 | J8: 1644 | K8: -19.4 | L8: ='119363 NORWALK_J 119480 NORWALK'!K8+'119363 NORWALK_J 119480 NORWALK'!M8 | M8: =U12 | N8: ='119363 NORWALK_J 119480 NORWALK'!L8/'119363 NORWALK_J 119480 NORWALK'!J8
A9: 5 | C9: 119363 NORWALK_J 345 119480 NORWALK 345 1 | I9: DC_3827_1655_NPCC_NERC | J9: 1644 | K9: -19.8 | L9: ='119363 NORWALK_J 119480 NORWALK'!K9+'119363 NORWALK_J 119480 NORWALK'!M9 | M9: =V12 | N9: ='119363 NORWALK_J 119480 NORWALK'!L9/'119363 NORWALK_J 119480 NORWALK'!J9
A12: Dispatch | J12: =SUM(J14:J737) | R12: =SUM(R14:R737) | S12: =SUM(S14:S737) | T12: =SUM(T14:T737) | U12: =SUM(U14:U737) | V12: =SUM(V14:V737)
A13: Bus# | B13: Bus Name | C13: Volt | D13: Area | E13: Zone | F13: Pgen or Pload | G13: PMin Gen | H13: PMax Gen | I13: Pnew | J13: Pdelta | K13: Pavail | L13: Dfax_1 | M13: Dfax_2 | N13: Dfax_3 | O13: Dfax_4 | P13: Dfax_5 | Q13: --- | R13: Impact_1 | S13: Impact_2 | T13: Impact_3 | U13: Impact_4 | V13: Impact_5
A14: 926261 | B14: NYPA - VT | C14: 345 | D14: 102 | E14: 12 | F14: 0 | G14: 0 | H14: 0 | I14: 0 | J14: =I14-F14 | K14: =H14-I14 | L14: 0.15587 | M14: 0.15353 | N14: 0.15667 | O14: 0.15667 | P14: 0.15655 | R14: =L14*J14 | S14: =M14*J14 | T14: =N14*J14 | U14: =O14*J14 | V14: =P14*J14
A15: 926260 | B15: NYPA - CMR | C15: 345 | D15: 102 | E15: 12 | F15: 0 | G15: 0 | H15: 0 | I15: 0 | J15: =I15-F15 | K15: =H15-I15 | L15: 0.15587 | M15: 0.15353 | N15: 0.15667 | O15: 0.15667 | P15: 0.15655 | R15: =L15*J15 | S15: =M15*J15 | T15: =N15*J15 | U15: =O15*J15 | V15: =P15*J15
A16: 911560 | B16: NYNE_BWLN | C16: 345 | D16: 102 | E16: 12 | F16: 120.67 | G16: 0 | H16: 466.67 | I16: 220.67 | J16: =I16-F16 | K16: =H16-I16 | L16: 0.15587 | M16: 0.15353 | N16: 0.15667 | O16: 0.15667 | P16: 0.15655 | R16: =L16*J16 | S16: =M16*J16 | T16: =N16*J16 | U16: =O16*J16 | V16: =P16*J16
A17: 109139 | B17: DEWEY MILLS | C17: 4.16 | D17: 101 | E17: 704 | F17: 0 | G17: 0 | H17: 0 | I17: 0 | J17: =I17-F17 | K17: =H17-I17 | L17: 0.1476 | M17: 0.14545 | N17: 0.14827 | O17: 0.14827 | P17: 0.14815 | R17: =L17*J17 | S17: =M17*J17 | T17: =N17*J17 | U17: =O17*J17 | V17: =P17*J17
A18: 107326 | B18: HG_CONVRTR_N | C18: 120 | D18: 101 | E18: 703 | F18: 0 | G18: 0 | H18: 0 | I18: 0 | J18: =I18-F18 | K18: =H18-I18 | L18: 0.1476 | M18: 0.14545 | N18: 0.14827 | O18: 0.14827 | P18: 0.14815 | R18: =L18*J18 | S18: =M18*J18 | T18: =N18*J18 | U18: =O18*J18 | V18: =P18*J18
A19: 108955 | B19: BELDENS1 | C19: 2.4 | D19: 101 | E19: 704 | F19: 0 | G19: 0 | H19: 0 | I19: 0 | J19: =I19-F19 | K19: =H19-I19 | L19: 0.1476 | M19: 0.14545 | N19: 0.14827 | O19: 0.14827 | P19: 0.14815 | R19: =L19*J19 | S19: =M19*J19 | T19: =N19*J19 | U19: =O19*J19 | V19: =P19*J19
A20: 109049 | B20: CARVER FALLS | C20: 2.3 | D20: 101 | E20: 704 | F20: 0 | G20: 0 | H20: 0 | I20: 0 | J20: =I20-F20 | K20: =H20-I20 | L20: 0.1476 | M20: 0.14545 | N20: 0.14827 | O20: 0.14827 | P20: 0.14815 | R20: =L20*J20 | S20: =M20*J20 | T20: =N20*J20 | U20: =O20*J20 | V20: =P20*J20
A21: 109077 | B21: E PITTSFORD | C21: 2.3 | D21: 101 | E21: 704 | F21: 0 | G21: 0 | H21: 0 | I21: 0 | J21: =I21-F21 | K21: =H21-I21 | L21: 0.1476 | M21: 0.14545 | N21: 0.14827 | O21: 0.14827 | P21: 0.14815 | R21: =L21*J21 | S21: =M21*J21 | T21: =N21*J21 | U21: =O21*J21 | V21: =P21*J21
A22: 109092 | B22: MIDDLESEX_G | C22: 2.4 | D22: 101 | E22: 704 | F22: 0 | G22: 0 | H22: 0 | I22: 0 | J22: =I22-F22 | K22: =H22-I22 | L22: 0.1476 | M22: 0.14545 | N22: 0.14827 | O22: 0.14827 | P22: 0.14815 | R22: =L22*J22 | S22: =M22*J22 | T22: =N22*J22 | U22: =O22*J22 | V22: =P22*J22
A23: 109101 | B23: SALISBURY | C23: 7.2 | D23: 101 | E23: 704 | F23: 0 | G23: 0 | H23: 0 | I23: 0 | J23: =I23-F23 | K23: =H23-I23 | L23: 0.1476 | M23: 0.14545 | N23: 0.14827 | O23: 0.14827 | P23: 0.14815 | R23: =L23*J23 | S23: =M23*J23 | T23: =N23*J23 | U23: =O23*J23 | V23: =P23*J23
A24: 109105 | B24: MIDDLEBURY_H | C24: 6.44 | D24: 101 | E24: 704 | F24: 0 | G24: 0 | H24: 0 | I24: 0 | J24: =I24-F24 | K24: =H24-I24 | L24: 0.1476 | M24: 0.14545 | N24: 0.14827 | O24: 0.14827 | P24: 0.14815 | R24: =L24*J24 | S24: =M24*J24 | T24: =N24*J24 | U24: =O24*J24 | V24: =P24*J24
A25: 109130 | B25: SMITH FALLS | C25: 4.16 | D25: 101 | E25: 704 | F25: 0 | G25: 0 | H25: 0 | I25: 0 | J25: =I25-F25 | K25: =H25-I25 | L25: 0.1476 | M25: 0.14545 | N25: 0.14827 | O25: 0.14827 | P25: 0.14815 | R25: =L25*J25 | S25: =M25*J25 | T25: =N25*J25 | U25: =O25*J25 | V25: =P25*J25
... A737: 123628 | B737: BRPT HRBR 5C | C737: 25 | D737: 101 | E737: 1803 | F737: 315.72 | G737: 0 | H737: 315.72 | I737: 315.72 | J737: =I737-F737 | K737: =H737-I737 | L737: -0.55724 | M737: -0.56357 | N737: -0.55205 | O737: -0.55205 | P737: -0.55229 | R737: =L737*J737 | S737: =M737*J737 | T737: =N737*J737 | U737: =O737*J737 | V737: =P737*J737

Sheet 137450 ALPS345 116034 NE
A1: ****** Plant Redispatch calculator ******* !!!! Please - edit only columns 'Status' & 'Pnew' !!!!!***
A3: Flows
A4: NN | B4: LFCaseName | C4: Monitored Element | I4: Contingency | J4: Limit | K4: FlowInit | L4: FlowRes | M4: FlowChange | N4: Loading
A5: 1 | C5: 137450 ALPS345 345 116034 NE_393_NY 345 1 | I5: BF_SEBRK_941 | J5: 1912 | K5: 1135.1 | L5: ='137450 ALPS345 116034 NE'!K5+'137450 ALPS345 116034 NE'!M5 | M5: =S13 | N5: ='137450 ALPS345 116034 NE'!L5/'137450 ALPS345 116034 NE'!J5
A6: 2 | C6: 137450 ALPS345 345 116034 NE_393_NY 345 1 | I6: GN_SBRK | J6: 1912 | K6: 1157.3 | L6: ='137450 ALPS345 116034 NE'!K6+'137450 ALPS345 116034 NE'!M6 | M6: =T13 | N6: ='137450 ALPS345 116034 NE'!L6/'137450 ALPS345 116034 NE'!J6
A7: 3 | C7: 137450 ALPS345 345 116034 NE_393_NY 345 1 | I7: TF_SBRK_GSU | J7: 1912 | K7: 1140.7 | L7: ='137450 ALPS345 116034 NE'!K7+'137450 ALPS345 116034 NE'!M7 | M7: =U13 | N7: ='137450 ALPS345 116034 NE'!L7/'137450 ALPS345 116034 NE'!J7
A8: 4 | C8: 137450 ALPS345 345 116034 NE_393_NY 345 1 | I8: GN_MIL3 | J8: 1912 | K8: 1048.6 | L8: ='137450 ALPS345 116034 NE'!K8+'137450 ALPS345 116034 NE'!M8 | M8: =V13 | N8: ='137450 ALPS345 116034 NE'!L8/'137450 ALPS345 116034 NE'!J8
A9: 5 | C9: 137450 ALPS345 345 116034 NE_393_NY 345 1 | I9: Base Case | J9: 1670 | K9: 754.2 | L9: ='137450 ALPS345 116034 NE'!K9+'137450 ALPS345 116034 NE'!M9 | M9: =W13 | N9: ='137450 ALPS345 116034 NE'!L9/'137450 ALPS345 116034 NE'!J9
A10: 6 | C10: 137450 ALPS345 345 116034 NE_393_NY 345 1 | I10: BF_SEBRK_169 | J10: 1912 | K10: 1138.6 | L10: ='137450 ALPS345 116034 NE'!K10+'137450 ALPS345 116034 NE'!M10 | M10: =X13 | N10: ='137450 ALPS345 116034 NE'!L10/'137450 ALPS345 116034 NE'!J10
A13: Dispatch | J13: =SUM(J15:J738) | S13: =SUM(S15:S738) | T13: =SUM(T15:T738) | U13: =SUM(U15:U738) | V13: =SUM(V15:V738) | W13: =SUM(W15:W738) | X13: =SUM(X15:X738)
A14: Bus# | B14: Bus Name | C14: Volt | D14: Area | E14: Zone | F14: Pgen or Pload | G14: PMin Gen | H14: PMax Gen | I14: Pnew | J14: Pdelta | K14: Pavail | L14: Dfax_1 | M14: Dfax_2 | N14: Dfax_3 | O14: Dfax_4 | P14: Dfax_5 | Q14: Dfax_6 | R14: --- | S14: Impact_1 | T14: Impact_2 | U14: Impact_3 | V14: Impact_4 | W14: Impact_5 | X14: Impact_6
A15: 999312 | B15: Strata_Ber~1 | C15: 115 | D15: 101 | E15: 1370 | F15: 0 | G15: 0 | H15: 0 | I15: -100 | J15: =I15-F15 | K15: =H15-I15 | L15: -0.18132 | M15: -0.18123 | N15: -0.18123 | O15: -0.18123 | P15: -0.18123 | Q15: -0.18118 | S15: =L15*J15 | T15: =M15*J15 | U15: =N15*J15 | V15: =O15*J15 | W15: =P15*J15 | X15: =Q15*J15
A16: 116608 | B16: DOREEN JET | C16: 13.2 | D16: 101 | E16: 1374 | F16: 0 | G16: 0 | H16: 0 | I16: 0 | J16: =I16-F16 | K16: =H16-I16 | L16: -0.16441 | M16: -0.16433 | N16: -0.16433 | O16: -0.16433 | P16: -0.16433 | Q16: -0.16428 | S16: =L16*J16 | T16: =M16*J16 | U16: =N16*J16 | V16: =O16*J16 | W16: =P16*J16 | X16: =Q16*J16
A17: 116618 | B17: ALTRESCO_C1 | C17: 13.8 | D17: 101 | E17: 1373 | F17: 33.65 | G17: 0 | H17: 33.65 | I17: 33.65 | J17: =I17-F17 | K17: =H17-I17 | L17: -0.16431 | M17: -0.16423 | N17: -0.16423 | O17: -0.16423 | P17: -0.16423 | Q17: -0.16418 | S17: =L17*J17 | T17: =M17*J17 | U17: =N17*J17 | V17: =O17*J17 | W17: =P17*J17 | X17: =Q17*J17
A18: 116619 | B18: ALTRESCO_C2 | C18: 13.8 | D18: 101 | E18: 1373 | F18: 33.65 | G18: 0 | H18: 33.65 | I18: 33.65 | J18: =I18-F18 | K18: =H18-I18 | L18: -0.16431 | M18: -0.16423 | N18: -0.16423 | O18: -0.16423 | P18: -0.16423 | Q18: -0.16418 | S18: =L18*J18 | T18: =M18*J18 | U18: =N18*J18 | V18: =O18*J18 | W18: =P18*J18 | X18: =Q18*J18
A19: 116620 | B19: ALTRESCO_C3 | C19: 13.8 | D19: 101 | E19: 1373 | F19: 31.45 | G19: 0 | H19: 33.65 | I19: 31.45 | J19: =I19-F19 | K19: =H19-I19 | L19: -0.16431 | M19: -0.16423 | N19: -0.16423 | O19: -0.16423 | P19: -0.16423 | Q19: -0.16418 | S19: =L19*J19 | T19: =M19*J19 | U19: =N19*J19 | V19: =O19*J19 | W19: =P19*J19 | X19: =Q19*J19
A20: 116621 | B20: ALTRESCO_S4 | C20: 13.8 | D20: 101 | E20: 1373 | F20: 0 | G20: 0 | H20: 0 | I20: 0 | J20: =I20-F20 | K20: =H20-I20 | L20: -0.16431 | M20: -0.16423 | N20: -0.16423 | O20: -0.16423 | P20: -0.16423 | Q20: -0.16418 | S20: =L20*J20 | T20: =M20*J20 | U20: =N20*J20 | V20: =O20*J20 | W20: =P20*J20 | X20: =Q20*J20
A21: 116638 | B21: WOODLAND JET | C21: 13.2 | D21: 101 | E21: 1374 | F21: 0 | G21: 0 | H21: 0 | I21: 0 | J21: =I21-F21 | K21: =H21-I21 | L21: -0.14273 | M21: -0.14266 | N21: -0.14266 | O21: -0.14266 | P21: -0.14266 | Q21: -0.14261 | S21: =L21*J21 | T21: =M21*J21 | U21: =N21*J21 | V21: =O21*J21 | W21: =P21*J21 | X21: =Q21*J21
A22: 116627 | B22: BERKSHRE WND | C22: 0.57 | D22: 101 | E22: 1374 | F22: 0 | G22: 0 | H22: 0 | I22: 0 | J22: =I22-F22 | K22: =H22-I22 | L22: -0.13404 | M22: -0.13396 | N22: -0.13396 | O22: -0.13396 | P22: -0.13396 | Q22: -0.13391 | S22: =L22*J22 | T22: =M22*J22 | U22: =N22*J22 | V22: =O22*J22 | W22: =P22*J22 | X22: =Q22*J22
A23: 996336 | B23: SUN BAT_PA~2 | C23: 115 | D23: 101 | E23: 1370 | F23: 0 | G23: 0 | H23: 0 | I23: 0 | J23: =I23-F23 | K23: =H23-I23 | L23: -0.13404 | M23: -0.13396 | N23: -0.13396 | O23: -0.13396 | P23: -0.13396 | Q23: -0.13391 | S23: =L23*J23 | T23: =M23*J23 | U23: =N23*J23 | V23: =O23*J23 | W23: =P23*J23 | X23: =Q23*J23
A24: 996625 | B24: SUN BAT_PA~1 | C24: 23 | D24: 101 | E24: 1372 | F24: 0 | G24: 0 | H24: 0 | I24: 0 | J24: =I24-F24 | K24: =H24-I24 | L24: -0.13404 | M24: -0.13396 | N24: -0.13396 | O24: -0.13396 | P24: -0.13396 | Q24: -0.13391 | S24: =L24*J24 | T24: =M24*J24 | U24: =N24*J24 | V24: =O24*J24 | W24: =P24*J24 | X24: =Q24*J24
A25: 116414 | B25: NORTHFIELD 4 | C25: 13.8 | D25: 101 | E25: 1373 | F25: 292 | G25: 0 | H25: 292 | I25: 292 | J25: =I25-F25 | K25: =H25-I25 | L25: -0.13246 | M25: -0.13228 | N25: -0.13228 | O25: -0.13228 | P25: -0.13228 | Q25: -0.13224 | S25: =L25*J25 | T25: =M25*J25 | U25: =N25*J25 | V25: =O25*J25 | W25: =P25*J25 | X25: =Q25*J25
