Workbook
Name IQ_CH: 110000
Name IQ_CQ: 5000
Name IQ_CY: 10000
Name IQ_DAILY: 500000
Name IQ_FH: 100000
Name IQ_FQ: 500
Name IQ_FY: 1000
Name IQ_LTM: 2000
Name IQ_MONTH: 15000
Name IQ_NTM: 6000
Name IQ_WEEK: 50000
Name IQ_YTD: 3000

Sheet PRDcalc (2)
A1: ****** Plant Redispatch calculator ******* !!!! Please - edit only columns 'Status' & 'Pnew' !!!!!***
A3: Flows
A4: NN | B4: LFCaseName | C4: Monitored Element | I4: Contingency | J4: Limit | K4: FlowInit | L4: FlowRes | M4: FlowChange | N4: Loading
A5: 1 | C5: 115711 SOMERSET 115 115714 DIGHTON_U6 115 1 | I5: BF_BRGWTR_13 | J5: 206 | K5: -9.4 | L5: ='PRDcalc (2)'!K5+'PRDcalc (2)'!M5 -> -9.4 | M5: =S13 -> 0 | N5: ='PRDcalc (2)'!L5/'PRDcalc (2)'!J5 -> -0.045631068
A6: 2 | C6: 115711 SOMERSET 115 115714 DIGHTON_U6 115 1 | I6: Base Case | J6: 191 | K6: -28.8 | L6: ='PRDcalc (2)'!K6+'PRDcalc (2)'!M6 -> -28.8 | M6: =T13 -> 0 | N6: ='PRDcalc (2)'!L6/'PRDcalc (2)'!J6 -> -0.15078534
A7: 3 | C7: 115711 SOMERSET 115 115714 DIGHTON_U6 115 1 | I7: LN_327 | J7: 206 | K7: -7.1 | L7: ='PRDcalc (2)'!K7+'PRDcalc (2)'!M7 -> -7.1 | M7: =U13 -> 0 | N7: ='PRDcalc (2)'!L7/'PRDcalc (2)'!J7 -> -0.034466019
A8: 4 | C8: 115711 SOMERSET 115 115714 DIGHTON_U6 115 1 | I8: BO_BELL_0320 | J8: 206 | K8: -0.1 | L8: ='PRDcalc (2)'!K8+'PRDcalc (2)'!M8 -> -0.1 | M8: =V13 -> 0 | N8: ='PRDcalc (2)'!L8/'PRDcalc (2)'!J8 -> -0.00048543689
A9: 5 | C9: 115711 SOMERSET 115 115714 DIGHTON_U6 115 1 | I9: BF_WMDWY_103 | J9: 206 | K9: -4.9 | L9: ='PRDcalc (2)'!K9+'PRDcalc (2)'!M9 -> -4.9 | M9: =W13 -> 0 | N9: ='PRDcalc (2)'!L9/'PRDcalc (2)'!J9 -> -0.023786408
A10: 6 | C10: 115711 SOMERSET 115 115714 DIGHTON_U6 115 1 | I10: BF_BERY_2703 | J10: 206 | K10: -7.7 | L10: ='PRDcalc (2)'!K10+'PRDcalc (2)'!M10 -> -7.7 | M10: =X13 -> 0 | N10: ='PRDcalc (2)'!L10/'PRDcalc (2)'!J10 -> -0.037378641
A13: Dispatch | J13: =SUM(J15:J715) -> 0 | S13: =SUM(S15:S715) -> 0 | T13: =SUM(T15:T715) -> 0 | U13: =SUM(U15:U715) -> 0 | V13: =SUM(V15:V715) -> 0 | W13: =SUM(W15:W715) -> 0 | X13: =SUM(X15:X715) -> 0
A14: Bus# | B14: Bus Name | C14: Volt | D14: Area | E14: Zone | F14: Pgen or Pload | G14: PMin Gen | H14: PMax Gen | I14: Pnew | J14: Pdelta | K14: Pavail | L14: Dfax_1 | M14: Dfax_2 | N14: Dfax_3 | O14: Dfax_4 | P14: Dfax_5 | Q14: Dfax_6 | R14: --- | S14: Impact_1 | T14: Impact_2 | U14: Impact_3 | V14: Impact_4 | W14: Impact_5 | X14: Impact_6
A15: 917355 | B15: DaymarkGe~80 | C15: 115 | D15: 101 | E15: 1410 | F15: 11.8 | G15: 0 | H15: 11.8 | I15: 11.8 | J15: =I15-F15 -> 0 | K15: =H15-I15 -> 0 | L15: 0.07886 | M15: 0.06949 | N15: 0.07694 | O15: 0.07908 | P15: 0.07934 | Q15: 0.07939 | S15: =L15*J15 -> 0 | T15: =M15*J15 -> 0 | U15: =N15*J15 -> 0 | V15: =O15*J15 -> 0 | W15: =P15*J15 -> 0 | X15: =Q15*J15 -> 0
A16: 117434 | B16: TIVERTON GT | C16: 18 | D16: 101 | E16: 1410 | F16: 173.41 | G16: 0 | H16: 173.41 | I16: 173.41 | J16: =I16-F16 -> 0 | K16: =H16-I16 -> 0 | L16: 0.07858 | M16: 0.06923 | N16: 0.07667 | O16: 0.07879 | P16: 0.07905 | Q16: 0.0791 | S16: =L16*J16 -> 0 | T16: =M16*J16 -> 0 | U16: =N16*J16 -> 0 | V16: =O16*J16 -> 0 | W16: =P16*J16 -> 0 | X16: =Q16*J16 -> 0
A17: 117435 | B17: TIVERTON ST | C17: 13.8 | D17: 101 | E17: 1410 | F17: 91.97 | G17: 0 | H17: 91.97 | I17: 91.97 | J17: =I17-F17 -> 0 | K17: =H17-I17 -> 0 | L17: 0.07858 | M17: 0.06923 | N17: 0.07667 | O17: 0.07879 | P17: 0.07905 | Q17: 0.0791 | S17: =L17*J17 -> 0 | T17: =M17*J17 -> 0 | U17: =N17*J17 -> 0 | V17: =O17*J17 -> 0 | W17: =P17*J17 -> 0 | X17: =Q17*J17 -> 0
A18: 918192 | B18: DaymarkGe~50 | C18: 115 | D18: 101 | E18: 1420 | F18: 21 | G18: 0 | H18: 21 | I18: 21 | J18: =I18-F18 -> 0 | K18: =H18-I18 -> 0 | L18: 0.07856 | M18: 0.06921 | N18: 0.07665 | O18: 0.07877 | P18: 0.07903 | Q18: 0.07908 | S18: =L18*J18 -> 0 | T18: =M18*J18 -> 0 | U18: =N18*J18 -> 0 | V18: =O18*J18 -> 0 | W18: =P18*J18 -> 0 | X18: =Q18*J18 -> 0
A19: 915728 | B19: DaymarkGe~12 | C19: 115 | D19: 101 | E19: 1160 | F19: 112.11 | G19: 0 | H19: 880 | I19: 112.11 | J19: =I19-F19 -> 0 | K19: =H19-I19 -> 767.89 | L19: 0.07223 | M19: 0.0636 | N19: 0.07052 | O19: 0.07247 | P19: 0.0727 | Q19: 0.07277 | S19: =L19*J19 -> 0 | T19: =M19*J19 -> 0 | U19: =N19*J19 -> 0 | V19: =O19*J19 -> 0 | W19: =P19*J19 -> 0 | X19: =Q19*J19 -> 0
A20: 995728 | B20: Daym_BELL ~1 | C20: 115 | D20: 101 | E20: 1160 | F20: 0 | G20: 0 | H20: 0 | I20: 0 | J20: =I20-F20 -> 0 | K20: =H20-I20 -> 0 | L20: 0.07223 | M20: 0.0636 | N20: 0.07052 | O20: 0.07247 | P20: 0.0727 | Q20: 0.07277 | S20: =L20*J20 -> 0 | T20: =M20*J20 -> 0 | U20: =N20*J20 -> 0 | V20: =O20*J20 -> 0 | W20: =P20*J20 -> 0 | X20: =Q20*J20 -> 0
A21: 917340 | B21: DaymarkGe~90 | C21: 115 | D21: 101 | E21: 1410 | F21: 6.93 | G21: 0 | H21: 6.93 | I21: 6.93 | J21: =I21-F21 -> 0 | K21: =H21-I21 -> 0 | L21: 0.05346 | M21: 0.04688 | N21: 0.05447 | O21: 0.05648 | P21: 0.05691 | Q21: 0.05682 | S21: =L21*J21 -> 0 | T21: =M21*J21 -> 0 | U21: =N21*J21 -> 0 | V21: =O21*J21 -> 0 | W21: =P21*J21 -> 0 | X21: =Q21*J21 -> 0
A22: 911265 | B22: DaymarkGe~40 | C22: 115 | D22: 101 | E22: 1050 | F22: 30.37 | G22: 0 | H22: 30.37 | I22: 30.37 | J22: =I22-F22 -> 0 | K22: =H22-I22 -> 0 | L22: 0.04814 | M22: 0.04223 | N22: 0.04719 | O22: 0.04848 | P22: 0.04856 | Q22: 0.04871 | S22: =L22*J22 -> 0 | T22: =M22*J22 -> 0 | U22: =N22*J22 -> 0 | V22: =O22*J22 -> 0 | W22: =P22*J22 -> 0 | X22: =Q22*J22 -> 0
A23: 911267 | B23: DaymarkGe~27 | C23: 115 | D23: 101 | E23: 1050 | F23: 0 | G23: 0 | H23: 0 | I23: 0 | J23: =I23-F23 -> 0 | K23: =H23-I23 -> 0 | L23: 0.04814 | M23: 0.04223 | N23: 0.04719 | O23: 0.04848 | P23: 0.04856 | Q23: 0.04871 | S23: =L23*J23 -> 0 | T23: =M23*J23 -> 0 | U23: =N23*J23 -> 0 | V23: =O23*J23 -> 0 | W23: =P23*J23 -> 0 | X23: =Q23*J23 -> 0
A24: 111316 | B24: DARTMTH PWRA | C24: 13.8 | D24: 101 | E24: 1053 | F24: 35.54 | G24: 0 | H24: 35.54 | I24: 35.54 | J24: =I24-F24 -> 0 | K24: =H24-I24 -> 0 | L24: 0.04805 | M24: 0.04216 | N24: 0.04711 | O24: 0.04839 | P24: 0.04848 | Q24: 0.04862 | S24: =L24*J24 -> 0 | T24: =M24*J24 -> 0 | U24: =N24*J24 -> 0 | V24: =O24*J24 -> 0 | W24: =P24*J24 -> 0 | X24: =Q24*J24 -> 0
A25: 111317 | B25: DARTMTH PWRB | C25: 13.8 | D25: 101 | E25: 1053 | F25: 21.06 | G25: 0 | H25: 21.3 | I25: 21.06 | J25: =I25-F25 -> 0 | K25: =H25-I25 -> 0.24 | L25: 0.04805 | M25: 0.04216 | N25: 0.04711 | O25: 0.04839 | P25: 0.04848 | Q25: 0.04862 | S25: =L25*J25 -> 0 | T25: =M25*J25 -> 0 | U25: =N25*J25 -> 0 | V25: =O25*J25 -> 0 | W25: =P25*J25 -> 0 | X25: =Q25*J25 -> 0
A26: 911279 | B26: DaymarkGe~30 | C26: 115 | D26: 101 | E26: 1050 | F26: 0 | G26: 0 | H26: 0 | I26: 0 | J26: =I26-F26 -> 0 | K26: =H26-I26 -> 0 | L26: 0.04805 | M26: 0.04216 | N26: 0.04711 | O26: 0.04839 | P26: 0.04848 | Q26: 0.04862 | S26: =L26*J26 -> 0 | T26: =M26*J26 -> 0 | U26: =N26*J26 -> 0 | V26: =O26*J26 -> 0 | W26: =P26*J26 -> 0 | X26: =Q26*J26 -> 0
... A610: 105478 | B610: NEWINGTON_S1 | C610: 18 | D610: 101 | E610: 603 | F610: 208.95 | G610: 0 | H610: 208.95 | I610: 208.95 | J610: =I610-F610 -> 0 | K610: =H610-I610 -> 0 | L610: -0.00316 | M610: -0.00315 | N610: -0.00427 | O610: -0.00501 | P610: -0.00524 | Q610: -0.00498 | S610: =L610*J610 -> 0 | T610: =M610*J610 -> 0 | U610: =N610*J610 -> 0 | V610: =O610*J610 -> 0 | W610: =P610*J610 -> 0 | X610: =Q610*J610 -> 0
A611: 105568 | B611: SEABROOK_G1 | C611: 25 | D611: 101 | E611: 603 | F611: 1134.47 | G611: 0 | H611: 1309.28 | I611: =1134.47 -> 1134.47 | J611: =I611-F611 -> 0 | K611: =H611-I611 -> 174.81 | L611: -0.00329 | M611: -0.00325 | N611: -0.0044 | O611: -0.00513 | P611: -0.00537 | Q611: -0.0051 | S611: =L611*J611 -> 0 | T611: =M611*J611 -> 0 | U611: =N611*J611 -> 0 | V611: =O611*J611 -> 0 | W611: =P611*J611 -> 0 | X611: =Q611*J611 -> 0
A612: 106056 | B612: GRANITE RDG1 | C612: 16 | D612: 101 | E612: 400 | F612: 223.08 | G612: 0 | H612: 223.08 | I612: 223.08 | J612: =I612-F612 -> 0 | K612: =H612-I612 -> 0 | L612: -0.00353 | M612: -0.00343 | N612: -0.00458 | O612: -0.00528 | P612: -0.00555 | Q612: -0.00526 | S612: =L612*J612 -> 0 | T612: =M612*J612 -> 0 | U612: =N612*J612 -> 0 | V612: =O612*J612 -> 0 | W612: =P612*J612 -> 0 | X612: =Q612*J612 -> 0
A613: 106057 | B613: GRANITE RDG2 | C613: 16 | D613: 101 | E613: 400 | F613: 223.08 | G613: 0 | H613: 223.08 | I613: 223.08 | J613: =I613-F613 -> 0 | K613: =H613-I613 -> 0 | L613: -0.00371 | M613: -0.00358 | N613: -0.00475 | O613: -0.00544 | P613: -0.00574 | Q613: -0.00543 | S613: =L613*J613 -> 0 | T613: =M613*J613 -> 0 | U613: =N613*J613 -> 0 | V613: =O613*J613 -> 0 | W613: =P613*J613 -> 0 | X613: =Q613*J613 -> 0
A614: 913968 | B614: DaymarkGe~13 | C614: 115 | D614: 101 | E614: 1120 | F614: 0 | G614: 0 | H614: 0 | I614: 0 | J614: =I614-F614 -> 0 | K614: =H614-I614 -> 0 | L614: -0.00379 | M614: -0.00365 | N614: -0.00486 | O614: -0.00556 | P614: -0.00586 | Q614: -0.00554 | S614: =L614*J614 -> 0 | T614: =M614*J614 -> 0 | U614: =N614*J614 -> 0 | V614: =O614*J614 -> 0 | W614: =P614*J614 -> 0 | X614: =Q614*J614 -> 0
A615: 114069 | B615: WHLABRATR NA | C615: 13.8 | D615: 101 | E615: 1120 | F615: 40 | G615: 0 | H615: 40 | I615: 40 | J615: =I615-F615 -> 0 | K615: =H615-I615 -> 0 | L615: -0.00383 | M615: -0.00369 | N615: -0.0049 | O615: -0.00562 | P615: -0.00592 | Q615: -0.0056 | S615: =L615*J615 -> 0 | T615: =M615*J615 -> 0 | U615: =N615*J615 -> 0 | V615: =O615*J615 -> 0 | W615: =P615*J615 -> 0 | X615: =Q615*J615 -> 0
A616: 114070 | B616: OGDEN-MARTIN | C616: 13.8 | D616: 101 | E616: 1120 | F616: 41.68 | G616: 0 | H616: 41.68 | I616: 41.68 | J616: =I616-F616 -> 0 | K616: =H616-I616 -> 0 | L616: -0.00383 | M616: -0.00369 | N616: -0.0049 | O616: -0.00562 | P616: -0.00592 | Q616: -0.0056 | S616: =L616*J616 -> 0 | T616: =M616*J616 -> 0 | U616: =N616*J616 -> 0 | V616: =O616*J616 -> 0 | W616: =P616*J616 -> 0 | X616: =Q616*J616 -> 0
A617: 114067 | B617: LAWRENCE HYD | C617: 4.16 | D617: 101 | E617: 1120 | F617: 9.4 | G617: 0 | H617: 9.4 | I617: 9.4 | J617: =I617-F617 -> 0 | K617: =H617-I617 -> 0 | L617: -0.00395 | M617: -0.00379 | N617: -0.005 | O617: -0.00571 | P617: -0.00602 | Q617: -0.00569 | S617: =L617*J617 -> 0 | T617: =M617*J617 -> 0 | U617: =N617*J617 -> 0 | V617: =O617*J617 -> 0 | W617: =P617*J617 -> 0 | X617: =Q617*J617 -> 0
A618: 114026 | B618: PERRY ST 3 | C618: 13.8 | D618: 101 | E618: 1120 | F618: 0 | G618: 0 | H618: 0 | I618: 0 | J618: =I618-F618 -> 0 | K618: =H618-I618 -> 0 | L618: -0.00409 | M618: -0.00389 | N618: -0.00512 | O618: -0.00582 | P618: -0.00615 | Q618: -0.00581 | S618: =L618*J618 -> 0 | T618: =M618*J618 -> 0 | U618: =N618*J618 -> 0 | V618: =O618*J618 -> 0 | W618: =P618*J618 -> 0 | X618: =Q618*J618 -> 0
A619: 114047 | B619: LENERGIA CT | C619: 13.8 | D619: 101 | E619: 1120 | F619: 50.43 | G619: 0 | H619: 50.43 | I619: 50.43 | J619: =I619-F619 -> 0 | K619: =H619-I619 -> 0 | L619: -0.00409 | M619: -0.00389 | N619: -0.00512 | O619: -0.00582 | P619: -0.00615 | Q619: -0.00581 | S619: =L619*J619 -> 0 | T619: =M619*J619 -> 0 | U619: =N619*J619 -> 0 | V619: =O619*J619 -> 0 | W619: =P619*J619 -> 0 | X619: =Q619*J619 -> 0
A620: 114048 | B620: LENERGIA ST | C620: 13.8 | D620: 101 | E620: 1120 | F620: 23.57 | G620: 0 | H620: 23.57 | I620: 23.57 | J620: =I620-F620 -> 0 | K620: =H620-I620 -> 0 | L620: -0.00409 | M620: -0.00389 | N620: -0.00512 | O620: -0.00582 | P620: -0.00615 | Q620: -0.00581 | S620: =L620*J620 -> 0 | T620: =M620*J620 -> 0 | U620: =N620*J620 -> 0 | V620: =O620*J620 -> 0 | W620: =P620*J620 -> 0 | X620: =Q620*J620 -> 0
A621: 114085 | B621: BOOT HYD G1 | C621: 4.16 | D621: 101 | E621: 1120 | F621: 0 | G621: 0 | H621: 0 | I621: 0 | J621: =I621-F621 -> 0 | K621: =H621-I621 -> 0 | L621: -0.00409 | M621: -0.00389 | N621: -0.00512 | O621: -0.00582 | P621: -0.00615 | Q621: -0.00581 | S621: =L621*J621 -> 0 | T621: =M621*J621 -> 0 | U621: =N621*J621 -> 0 | V621: =O621*J621 -> 0 | W621: =P621*J621 -> 0 | X621: =Q621*J621 -> 0
A622: 114086 | B622: BOOT HYD G2 | C622: 4.16 | D622: 101 | E622: 1120 | F622: 0 | G622: 0 | H622: 0 | I622: 0 | J622: =I622-F622 -> 0 | K622: =H622-I622 -> 0 | L622: -0.00409 | M622: -0.00389 | N622: -0.00512 | O622: -0.00582 | P622: -0.00615 | Q622: -0.00581 | S622: =L622*J622 -> 0 | T622: =M622*J622 -> 0 | U622: =N622*J622 -> 0 | V622: =O622*J622 -> 0 | W622: =P622*J622 -> 0 | X622: =Q622*J622 -> 0
A623: 910770 | B623: DaymarkGe~98 | C623: 345 | D623: 101 | E623: 1020 | F623: 250 | G623: 0 | H623: 250 | I623: 250 | J623: =I623-F623 -> 0 | K623: =H623-I623 -> 0 | L623: -0.00424 | M623: -0.00458 | N623: -0.00747 | O623: -0.00933 | P623: -0.01177 | Q623: -0.00925 | S623: =L623*J623 -> 0 | T623: =M623*J623 -> 0 | U623: =N623*J623 -> 0 | V623: =O623*J623 -> 0 | W623: =P623*J623 -> 0 | X623: =Q623*J623 -> 0
... A715: 995714 | B715: TJA_Dight | C715: 115 | D715: 101 | E715: 1160 | F715: 0 | G715: 0 | H715: 0 | I715: 0 | J715: =I715-F715 -> 0 | K715: =H715-I715 -> 0 | L715: -0.63052 | M715: -0.62637 | N715: -0.62088 | O715: -0.61938 | P715: -0.61917 | Q715: -0.61914 | S715: =L715*J715 -> 0 | T715: =M715*J715 -> 0 | U715: =N715*J715 -> 0 | V715: =O715*J715 -> 0 | W715: =P715*J715 -> 0 | X715: =Q715*J715 -> 0

Sheet PRDcalc
A1: ****** Plant Redispatch calculator ******* !!!! Please - edit only columns 'Status' & 'Pnew' !!!!!***
A3: Flows
A4: NN | B4: LFCaseName | C4: Monitored Element | I4: Contingency | J4: Limit | K4: FlowInit | L4: FlowRes | M4: FlowChange | N4: Loading
A5: 1 | C5: 115714 DIGHTON_U6 115 115711 SOMERSET 115 1 | I5: NF_U6-4 | J5: 206 | K5: 148.7 | L5: =PRDcalc!K5+PRDcalc!M5 -> 148.7 | M5: =R12 -> 0 | N5: =PRDcalc!L5/PRDcalc!J5 -> 0.72184466
A6: 2 | C6: 115714 DIGHTON_U6 115 115711 SOMERSET 115 1 | I6: BF_JEPSN_L14 | J6: 206 | K6: 33.5 | L6: =PRDcalc!K6+PRDcalc!M6 -> 33.5 | M6: =S12 -> 0 | N6: =PRDcalc!L6/PRDcalc!J6 -> 0.16262136
A7: 3 | C7: 115714 DIGHTON_U6 115 115711 SOMERSET 115 1 | I7: LN_L14 | J7: 206 | K7: 33.5 | L7: =PRDcalc!K7+PRDcalc!M7 -> 33.5 | M7: =T12 -> 0 | N7: =PRDcalc!L7/PRDcalc!J7 -> 0.16262136
A8: 4 | C8: 115714 DIGHTON_U6 115 115711 SOMERSET 115 1 | I8: BF_JEPSN_4T3 | J8: 206 | K8: 32.7 | L8: =PRDcalc!K8+PRDcalc!M8 -> 32.7 | M8: =U12 -> 0 | N8: =PRDcalc!L8/PRDcalc!J8 -> 0.15873786
A9: 5 | C9: 115714 DIGHTON_U6 115 115711 SOMERSET 115 1 | I9: BF_BELLRK_02 | J9: 206 | K9: 32 | L9: =PRDcalc!K9+PRDcalc!M9 -> 32 | M9: =V12 -> 0 | N9: =PRDcalc!L9/PRDcalc!J9 -> 0.15533981
A12: Dispatch | J12: =SUM(J14:J714) -> 0 | R12: =SUM(R14:R714) -> 0 | S12: =SUM(S14:S714) -> 0 | T12: =SUM(T14:T714) -> 0 | U12: =SUM(U14:U714) -> 0 | V12: =SUM(V14:V714) -> 0
A13: Bus# | B13: Bus Name | C13: Volt | D13: Area | E13: Zone | F13: Pgen or Pload | G13: PMin Gen | H13: PMax Gen | I13: Pnew | J13: Pdelta | K13: Pavail | L13: Dfax_1 | M13: Dfax_2 | N13: Dfax_3 | O13: Dfax_4 | P13: Dfax_5 | Q13: --- | R13: Impact_1 | S13: Impact_2 | T13: Impact_3 | U13: Impact_4 | V13: Impact_5
A14: 115742 | B14: DIGHTON PWR | C14: 22 | D14: 101 | E14: 1160 | F14: 168 | G14: 0 | H14: 168 | I14: 168 | J14: =I14-F14 -> 0 | K14: =H14-I14 -> 0 | L14: 0.99934 | M14: 0.57668 | N14: 0.57668 | O14: 0.57665 | P14: 0.57662 | R14: =L14*J14 -> 0 | S14: =M14*J14 -> 0 | T14: =N14*J14 -> 0 | U14: =O14*J14 -> 0 | V14: =P14*J14 -> 0
A15: 995714 | B15: TJA_Dight | C15: 115 | D15: 101 | E15: 1160 | F15: 0 | G15: 0 | H15: 0 | I15: 0 | J15: =I15-F15 -> 0 | K15: =H15-I15 -> 0 | L15: 0.99934 | M15: 0.62026 | N15: 0.62026 | O15: 0.62023 | P15: 0.6202 | R15: =L15*J15 -> 0 | S15: =M15*J15 -> 0 | T15: =N15*J15 -> 0 | U15: =O15*J15 -> 0 | V15: =P15*J15 -> 0
A16: 100351 | B16: KIBBY STRNG1 | C16: 1 | D16: 101 | E16: 144 | F16: 6.03 | G16: 0 | H16: 6.03 | I16: 6.03 | J16: =I16-F16 -> 0 | K16: =H16-I16 -> 0 | L16: -0.00066 | M16: 0.00274 | N16: 0.00274 | O16: 0.00271 | P16: 0.00268 | R16: =L16*J16 -> 0 | S16: =M16*J16 -> 0 | T16: =N16*J16 -> 0 | U16: =O16*J16 -> 0 | V16: =P16*J16 -> 0
A17: 100352 | B17: KIBBY STRNG2 | C17: 1 | D17: 101 | E17: 144 | F17: 0 | G17: 0 | H17: 0 | I17: 0 | J17: =I17-F17 -> 0 | K17: =H17-I17 -> 0 | L17: -0.00066 | M17: 0.00274 | N17: 0.00274 | O17: 0.00271 | P17: 0.00268 | R17: =L17*J17 -> 0 | S17: =M17*J17 -> 0 | T17: =N17*J17 -> 0 | U17: =O17*J17 -> 0 | V17: =P17*J17 -> 0
A18: 100353 | B18: KIBBY STRNG3 | C18: 1 | D18: 101 | E18: 144 | F18: 6.03 | G18: 0 | H18: 6.03 | I18: 6.03 | J18: =I18-F18 -> 0 | K18: =H18-I18 -> 0 | L18: -0.00066 | M18: 0.00274 | N18: 0.00274 | O18: 0.00271 | P18: 0.00268 | R18: =L18*J18 -> 0 | S18: =M18*J18 -> 0 | T18: =N18*J18 -> 0 | U18: =O18*J18 -> 0 | V18: =P18*J18 -> 0
A19: 100354 | B19: KIBBY STRNG4 | C19: 1 | D19: 101 | E19: 144 | F19: 4.17 | G19: 0 | H19: 4.17 | I19: 4.17 | J19: =I19-F19 -> 0 | K19: =H19-I19 -> 0 | L19: -0.00066 | M19: 0.00274 | N19: 0.00274 | O19: 0.00271 | P19: 0.00268 | R19: =L19*J19 -> 0 | S19: =M19*J19 -> 0 | T19: =N19*J19 -> 0 | U19: =O19*J19 -> 0 | V19: =P19*J19 -> 0
A20: 100355 | B20: KIBBY W DVAR | C20: 34.5 | D20: 101 | E20: 144 | F20: 0 | G20: 0 | H20: 0 | I20: 0 | J20: =I20-F20 -> 0 | K20: =H20-I20 -> 0 | L20: -0.00066 | M20: 0.00274 | N20: 0.00274 | O20: 0.00271 | P20: 0.00268 | R20: =L20*J20 -> 0 | S20: =M20*J20 -> 0 | T20: =N20*J20 -> 0 | U20: =O20*J20 -> 0 | V20: =P20*J20 -> 0
A21: 100356 | B21: HARRIS HY T1 | C21: 13.8 | D21: 101 | E21: 113 | F21: 17 | G21: 0 | H21: 17 | I21: 17 | J21: =I21-F21 -> 0 | K21: =H21-I21 -> 0 | L21: -0.00066 | M21: 0.00274 | N21: 0.00274 | O21: 0.00271 | P21: 0.00268 | R21: =L21*J21 -> 0 | S21: =M21*J21 -> 0 | T21: =N21*J21 -> 0 | U21: =O21*J21 -> 0 | V21: =P21*J21 -> 0
A22: 100357 | B22: HARRIS HY T2 | C22: 13.8 | D22: 101 | E22: 113 | F22: 0 | G22: 0 | H22: 0 | I22: 0 | J22: =I22-F22 -> 0 | K22: =H22-I22 -> 0 | L22: -0.00066 | M22: 0.00274 | N22: 0.00274 | O22: 0.00271 | P22: 0.00268 | R22: =L22*J22 -> 0 | S22: =M22*J22 -> 0 | T22: =N22*J22 -> 0 | U22: =O22*J22 -> 0 | V22: =P22*J22 -> 0
A23: 100358 | B23: HARRIS HY T3 | C23: 13.8 | D23: 101 | E23: 113 | F23: 0 | G23: 0 | H23: 0 | I23: 0 | J23: =I23-F23 -> 0 | K23: =H23-I23 -> 0 | L23: -0.00066 | M23: 0.00274 | N23: 0.00274 | O23: 0.00271 | P23: 0.00268 | R23: =L23*J23 -> 0 | S23: =M23*J23 -> 0 | T23: =N23*J23 -> 0 | U23: =O23*J23 -> 0 | V23: =P23*J23 -> 0
A24: 100359 | B24: VERJAY RILEY | C24: 2.4 | D24: 101 | E24: 114 | F24: 0 | G24: 0 | H24: 0 | I24: 0 | J24: =I24-F24 -> 0 | K24: =H24-I24 -> 0 | L24: -0.00066 | M24: 0.00274 | N24: 0.00274 | O24: 0.00271 | P24: 0.00268 | R24: =L24*J24 -> 0 | S24: =M24*J24 -> 0 | T24: =N24*J24 -> 0 | U24: =O24*J24 -> 0 | V24: =P24*J24 -> 0
A25: 100360 | B25: WYMAN HYD#1 | C25: 13.8 | D25: 101 | E25: 113 | F25: 29.01 | G25: 0 | H25: 29.01 | I25: 29.01 | J25: =I25-F25 -> 0 | K25: =H25-I25 -> 0 | L25: -0.00066 | M25: 0.00274 | N25: 0.00274 | O25: 0.00271 | P25: 0.00268 | R25: =L25*J25 -> 0 | S25: =M25*J25 -> 0 | T25: =N25*J25 -> 0 | U25: =O25*J25 -> 0 | V25: =P25*J25 -> 0
... A356: 113085 | B356: WENDELL DEP | C356: 13.8 | D356: 101 | E356: 1100 | F356: 0 | G356: 0 | H356: 0 | I356: 0 | J356: =I356-F356 -> 0 | K356: =H356-I356 -> 0 | L356: -0.00066 | M356: -0.00184 | N356: -0.00184 | O356: -0.00187 | P356: -0.0019 | R356: =L356*J356 -> 0 | S356: =M356*J356 -> 0 | T356: =N356*J356 -> 0 | U356: =O356*J356 -> 0 | V356: =P356*J356 -> 0
A357: 113096 | B357: BEARSWAMP 1 | C357: 13.8 | D357: 101 | E357: 1100 | F357: 331.5 | G357: 0 | H357: 331.5 | I357: =331.5 -> 331.5 | J357: =I357-F357 -> 0 | K357: =H357-I357 -> 0 | L357: -0.00066 | M357: -0.00146 | N357: -0.00146 | O357: -0.00149 | P357: -0.00151 | R357: =L357*J357 -> 0 | S357: =M357*J357 -> 0 | T357: =N357*J357 -> 0 | U357: =O357*J357 -> 0 | V357: =P357*J357 -> 0
A358: 113097 | B358: BEARSWAMP 2 | C358: 13.8 | D358: 101 | E358: 1100 | F358: 331.5 | G358: 0 | H358: 331.5 | I358: 331.5 | J358: =I358-F358 -> 0 | K358: =H358-I358 -> 0 | L358: -0.00066 | M358: -0.00146 | N358: -0.00146 | O358: -0.00149 | P358: -0.00151 | R358: =L358*J358 -> 0 | S358: =M358*J358 -> 0 | T358: =N358*J358 -> 0 | U358: =O358*J358 -> 0 | V358: =P358*J358 -> 0
A359: 113098 | B359: DEERFIELD 2G | C359: 2.4 | D359: 101 | E359: 1100 | F359: 0 | G359: 0 | H359: 0 | I359: 0 | J359: =I359-F359 -> 0 | K359: =H359-I359 -> 0 | L359: -0.00066 | M359: -0.00163 | N359: -0.00163 | O359: -0.00166 | P359: -0.00169 | R359: =L359*J359 -> 0 | S359: =M359*J359 -> 0 | T359: =N359*J359 -> 0 | U359: =O359*J359 -> 0 | V359: =P359*J359 -> 0
A360: 113099 | B360: DEERFIELD 3G | C360: 2.4 | D360: 101 | E360: 1100 | F360: 0 | G360: 0 | H360: 0 | I360: 0 | J360: =I360-F360 -> 0 | K360: =H360-I360 -> 0 | L360: -0.00066 | M360: -0.00158 | N360: -0.00158 | O360: -0.00161 | P360: -0.00164 | R360: =L360*J360 -> 0 | S360: =M360*J360 -> 0 | T360: =N360*J360 -> 0 | U360: =O360*J360 -> 0 | V360: =P360*J360 -> 0
A361: 113100 | B361: DEERFIELD 4G | C361: 2.4 | D361: 101 | E361: 1100 | F361: 0 | G361: 0 | H361: 0 | I361: 0 | J361: =I361-F361 -> 0 | K361: =H361-I361 -> 0 | L361: -0.00066 | M361: -0.00154 | N361: -0.00154 | O361: -0.00157 | P361: -0.0016 | R361: =L361*J361 -> 0 | S361: =M361*J361 -> 0 | T361: =N361*J361 -> 0 | U361: =O361*J361 -> 0 | V361: =P361*J361 -> 0
A362: 113101 | B362: DEERFIELD 5G | C362: 13.8 | D362: 101 | E362: 1100 | F362: 0 | G362: 0 | H362: 0 | I362: 0 | J362: =I362-F362 -> 0 | K362: =H362-I362 -> 0 | L362: -0.00066 | M362: -0.00173 | N362: -0.00173 | O362: -0.00176 | P362: -0.00179 | R362: =L362*J362 -> 0 | S362: =M362*J362 -> 0 | T362: =N362*J362 -> 0 | U362: =O362*J362 -> 0 | V362: =P362*J362 -> 0
A363: 113102 | B363: FIFE BROOK | C363: 13.8 | D363: 101 | E363: 1100 | F363: 9.9 | G363: 0 | H363: 9.9 | I363: 9.9 | J363: =I363-F363 -> 0 | K363: =H363-I363 -> 0 | L363: -0.00066 | M363: -0.00173 | N363: -0.00173 | O363: -0.00176 | P363: -0.00179 | R363: =L363*J363 -> 0 | S363: =M363*J363 -> 0 | T363: =N363*J363 -> 0 | U363: =O363*J363 -> 0 | V363: =P363*J363 -> 0
A364: 113104 | B364: SHERMAN HYD | C364: 2.4 | D364: 101 | E364: 1100 | F364: 0 | G364: 0 | H364: 0 | I364: 0 | J364: =I364-F364 -> 0 | K364: =H364-I364 -> 0 | L364: -0.00066 | M364: -0.00175 | N364: -0.00175 | O364: -0.00178 | P364: -0.0018 | R364: =L364*J364 -> 0 | S364: =M364*J364 -> 0 | T364: =N364*J364 -> 0 | U364: =O364*J364 -> 0 | V364: =P364*J364 -> 0
A365: 113123 | B365: HOOSAC CLR1 | C365: 0.69 | D365: 101 | E365: 1100 | F365: 0 | G365: 0 | H365: 0 | I365: 0 | J365: =I365-F365 -> 0 | K365: =H365-I365 -> 0 | L365: -0.00066 | M365: -0.00174 | N365: -0.00174 | O365: -0.00177 | P365: -0.00179 | R365: =L365*J365 -> 0 | S365: =M365*J365 -> 0 | T365: =N365*J365 -> 0 | U365: =O365*J365 -> 0 | V365: =P365*J365 -> 0
A366: 113125 | B366: HOOSAC CLR2 | C366: 0.69 | D366: 101 | E366: 1100 | F366: 0 | G366: 0 | H366: 0 | I366: 0 | J366: =I366-F366 -> 0 | K366: =H366-I366 -> 0 | L366: -0.00066 | M366: -0.00174 | N366: -0.00174 | O366: -0.00177 | P366: -0.00179 | R366: =L366*J366 -> 0 | S366: =M366*J366 -> 0 | T366: =N366*J366 -> 0 | U366: =O366*J366 -> 0 | V366: =P366*J366 -> 0
A367: 113128 | B367: WARREN_A | C367: 0.34 | D367: 101 | E367: 1100 | F367: 0 | G367: 0 | H367: 0 | I367: 0 | J367: =I367-F367 -> 0 | K367: =H367-I367 -> 0 | L367: -0.00066 | M367: -0.00185 | N367: -0.00185 | O367: -0.00188 | P367: -0.0019 | R367: =L367*J367 -> 0 | S367: =M367*J367 -> 0 | T367: =N367*J367 -> 0 | U367: =O367*J367 -> 0 | V367: =P367*J367 -> 0
A368: 113129 | B368: WARREN_B | C368: 0.34 | D368: 101 | E368: 1100 | F368: 0 | G368: 0 | H368: 0 | I368: 0 | J368: =I368-F368 -> 0 | K368: =H368-I368 -> 0 | L368: -0.00066 | M368: -0.00185 | N368: -0.00185 | O368: -0.00188 | P368: -0.0019 | R368: =L368*J368 -> 0 | S368: =M368*J368 -> 0 | T368: =N368*J368 -> 0 | U368: =O368*J368 -> 0 | V368: =P368*J368 -> 0
A369: 113130 | B369: WARREN_C | C369: 0.36 | D369: 101 | E369: 1100 | F369: 0 | G369: 0 | H369: 0 | I369: 0 | J369: =I369-F369 -> 0 | K369: =H369-I369 -> 0 | L369: -0.00066 | M369: -0.00185 | N369: -0.00185 | O369: -0.00188 | P369: -0.0019 | R369: =L369*J369 -> 0 | S369: =M369*J369 -> 0 | T369: =N369*J369 -> 0 | U369: =O369*J369 -> 0 | V369: =P369*J369 -> 0
... A378: 113404 | B378: WMI MILLBURY | C378: 13.8 | D378: 101 | E378: 1110 | F378: 40.94 | G378: 0 | H378: 40.94 | I378: 40.94 | J378: =I378-F378 -> 0 | K378: =H378-I378 -> 0 | L378: -0.00066 | M378: -0.0041 | N378: -0.0041 | O378: -0.00413 | P378: -0.00415 | R378: =L378*J378 -> 0 | S378: =M378*J378 -> 0 | T378: =N378*J378 -> 0 | U378: =O378*J378 -> 0 | V378: =P378*J378 -> 0
A379: 113405 | B379: MILLENIUM CT | C379: 16 | D379: 101 | E379: 1110 | F379: 228.56 | G379: 0 | H379: 228.56 | I379: =228.56 -> 228.56 | J379: =I379-F379 -> 0 | K379: =H379-I379 -> 0 | L379: -0.00066 | M379: -0.0016 | N379: -0.0016 | O379: -0.00163 | P379: -0.00165 | R379: =L379*J379 -> 0 | S379: =M379*J379 -> 0 | T379: =N379*J379 -> 0 | U379: =O379*J379 -> 0 | V379: =P379*J379 -> 0
A380: 113406 | B380: MILLENIUM ST | C380: 13.8 | D380: 101 | E380: 1110 | F380: 102.44 | G380: 0 | H380: 102.44 | I380: 102.44 | J380: =I380-F380 -> 0 | K380: =H380-I380 -> 0 | L380: -0.00066 | M380: -0.0016 | N380: -0.0016 | O380: -0.00163 | P380: -0.00165 | R380: =L380*J380 -> 0 | S380: =M380*J380 -> 0 | T380: =N380*J380 -> 0 | U380: =O380*J380 -> 0 | V380: =P380*J380 -> 0
A381: 113429 | B381: FRENCH_B1 | C381: 0.48 | D381: 101 | E381: 1110 | F381: 0 | G381: 0 | H381: 0 | I381: 0 | J381: =I381-F381 -> 0 | K381: =H381-I381 -> 0 | L381: -0.00066 | M381: -0.00262 | N381: -0.00262 | O381: -0.00265 | P381: -0.00268 | R381: =L381*J381 -> 0 | S381: =M381*J381 -> 0 | T381: =N381*J381 -> 0 | U381: =O381*J381 -> 0 | V381: =P381*J381 -> 0
...
